Workbook

Sheet Cover
B2: DIXON TECHNOLOGIES (INDIA) LTD. | NSE: DIXON | BSE: 541988
B4: 3-Statement Financial Model & Discounted Cash Flow (DCF) Valuation
B6: Analyst | C6: Om Chaudhari
B7: Institution | C7: Indian Institute of Technology, Bombay — B.Tech (Year 2)
B8: Date | C8: June 2026
B9: Currency | C9: ₹ Indian Rupee | Unit: Crore (₹ Cr)
B10: Fiscal Year | C10: April 1 – March 31 (Indian FY)
B11: Exchange | C11: NSE / BSE | ISIN: INE424L01029
B12: Scope | C12: FY22A–FY25A (Actual) + FY26E–FY30E (Forecast)
B13: Model Version | C13: v2.0 (8-tab structure, WACC merged into DCF)
A16: COMPANY OVERVIEW
B17: Dixon Technologies (India) Ltd. is India's largest Electronics Manufacturing Services (EMS) company. Founded in 1993 and listed on NSE & BSE, Dixon manufactures across six verticals: Consumer Electronics (LED TVs, monitors), Home Appliances (washing machines), Lighting Products (LED lamps/luminaires), Mobile & EMS (smartphones under PLI scheme), Security Surveillance (CCTV/DVRs), and Wearables & IT Hardware (laptops, tablets). Dixon is a primary beneficiary of India's Production-Linked Incentive (PLI) schemes and the 'China+1' global supply-chain diversification theme. Key OEM partners include Samsung, Motorola, OnePlus, Xiaomi, Google, and HP. Management has guided for ₹1,00,000 Cr+ revenue by FY27.
A24: KEY FINANCIAL HIGHLIGHTS (₹ Crore)
B25: Metric | C25: FY22A | D25: FY23A | E25: FY24A | F25: FY25A
B26: Revenue (₹ Cr) | C26: 10,697 | D26: 12,192 | E26: 17,691 | F26: 38,860
B27: YoY Revenue Growth | C27: — | D27: +14% | E27: +45% | F27: +120%
B28: EBITDA (₹ Cr) | C28: 430 | D28: 510 | E28: 708 | F28: 1,943
B29: EBITDA Margin % | C29: 4.0% | D29: 4.2% | E29: 4.0% | F29: 5.0%
B30: PAT (₹ Cr) | C30: 190 | D30: 253 | E30: 365 | F30: 1,215
B31: PAT Margin % | C31: 1.8% | D31: 2.1% | E31: 2.1% | F31: 3.1%
B32: EPS (₹) | C32: 31.7 | D32: 42.2 | E32: 60.9 | F32: 202.8
B33: ROE | C33: 17% | D33: 19% | E33: 21% | F33: 42%
A36: WORKBOOK STRUCTURE (8 Tabs)
B37: 1. Cover | C37: This page — project overview, key metrics, navigation guide
B38: 2. ASSUMP | C38: All model inputs & assumptions — edit ONLY this tab to change forecasts
B39: 3. IS | C39: Income Statement — P&L with Ratio Analysis (WiDS Week 1 & 2)
B40: 4. BS | C40: Balance Sheet — formula-linked to IS & CF
B41: 5. CF | C41: Cash Flow Statement — indirect method, formula-linked
B42: 6. DCF | C42: WACC derivation + FCFF model + EV bridge → Implied Share Price (Weeks 3-4)
B43: 7. SENSITIVITY | C43: 2-Way sensitivity table: Implied Price vs WACC & Terminal Growth Rate
B44: 8. COMPS | C44: Peer Comparables — Dixon vs Amber, Kaynes, Syrma (relative valuation)
A47: COLOR CODING CONVENTION
B48: ■ Blue text | C48: Hardcoded inputs — source: Annual Reports / Damodaran / RBI
B49: ■ Black text | C49: Formula cells — calculated automatically, do NOT edit
B50: ■ Green text | C50: Cross-sheet links — pulling values from another tab
B51: ■ Yellow fill | C51: Key assumption cell — verify before presenting
B54: Sources: Dixon Annual Reports FY22–FY25 (BSE/NSE) | Screener.in | Trendlyne | Damodaran ERP (India) | RBI 10-yr G-Sec | Motilal Oswal / ICICI Direct Research

Sheet ASSUMP
A1: DIXON TECHNOLOGIES — MODEL ASSUMPTIONS (Edit ONLY blue cells)
A3: INCOME STATEMENT DRIVERS
A4: Assumption | B4: Value / Rate | C4: Notes / Source
A5: Revenue Growth — FY26E | B5: 0.3 | C5: 30% YoY; Dixon guided ₹50,000Cr+; PLI-driven mobile ramp-up
A6: Revenue Growth — FY27E | B6: 0.25 | C6: 25% YoY; continued EMS expansion + new category wins
A7: Revenue Growth — FY28E | B7: 0.18 | C7: 18% YoY; growth normalisation, base effect kicking in
A8: Revenue Growth — FY29E | B8: 0.15 | C8: 15% YoY; stable EMS market share gains
A9: Revenue Growth — FY30E | B9: 0.12 | C9: 12% YoY; mature growth phase, diversified revenue base
A10: EBITDA Margin % (all yrs) | B10: 0.052 | C10: 5.2%; slight margin expansion from operating leverage & PLI income
A11: D&A as % of Revenue | B11: 0.008 | C11: 0.8%; low asset-light model; capex mostly leased equipment
A12: Effective Tax Rate | B12: 0.25 | C12: 25%; new tax regime post FY22; Source: Dixon Annual Reports
A13: Pre-tax Cost of Debt (Kd) | B13: 0.085 | C13: 8.5%; ~repo rate + 200bps; RBI repo at 6.5% as of June 2026
A15: BALANCE SHEET & CASH FLOW DRIVERS
A16: Assumption | B16: Value / Rate | C16: Notes / Source
A17: Capex as % of Revenue | B17: 0.02 | C17: 2.0%; asset-light EMS; light capex relative to scale
A18: NWC as % of Revenue | B18: 0.045 | C18: 4.5%; Dixon historically runs lean working capital cycles
A19: Shares Outstanding (lakhs) | B19: 600 | C19: 6.0 crore shares = 600 lakh shares; Source: NSE/BSE filings
A21: WACC / CAPM INPUTS (Week 3 — WiDS)
A22: Parameter | B22: Value | C22: Notes / Source
A24: Risk-Free Rate (Rf) | B24: 0.07 | C24: 7.0%; India 10-yr G-Sec yield (RBI, June 2026)
A25: Equity Risk Premium (ERP) | B25: 0.06 | C25: 6.0%; Damodaran India ERP (Jan 2026 update)
A26: Beta (β) — Levered | B26: 1.4 | C26: 1.40; regressed vs. Nifty 50 (2-yr weekly); EMS sector cyclical
A27: Cost of Equity Ke = Rf+β×ERP | B27: =B24+B26*B25 | C27: CAPM: 7.0% + 1.40×6.0% = 15.4%
A28: Debt Weight D/(D+E) | B28: 0.2 | C28: 20%; conservative; Dixon is equity-heavy; Source: BS FY25
A29: Pre-tax Kd (gross) | B29: =B13 | C29: Linked from IS Drivers above
A30: After-tax Kd = Kd×(1-Tax) | B30: =B29*(1-B12) | C30: 8.5%×(1-25%) = 6.375%
A31: WACC = Ke×(1-D%) + Kd×D% | B31: =B27*(1-B28)+B30*B28 | C31: ≈ 13.6%; weighted avg cost of capital
A33: TERMINAL VALUE INPUT (Week 3 — WiDS)
A34: Parameter | B34: Value | C34: Notes / Source
A35: Terminal Growth Rate (g) | B35: 0.055 | C35: 5.5%; long-run India nominal GDP growth proxy; conservative vs EMS sector
A37: DATA SOURCES & LINKS
A38: Dixon AR FY25 (BSE): https://www.bseindia.com/bseplus/AnnualReport/541988/10124541988.pdf
A39: Dixon AR FY24 (BSE): https://www.bseindia.com/bseplus/AnnualReport/541988/10124541988.pdf
A40: Screener.in (Consolidated P&L/BS/CF): https://www.screener.in/company/DIXON/consolidated/
A41: Trendlyne (financials + ratios): https://trendlyne.com/equity/1624/DIXON/
A42: Damodaran ERP India: https://pages.stern.nyu.edu/~adamodar/New_Home_Page/datafile/ctryprem.html
A43: RBI G-Sec yields: https://www.rbi.org.in/Scripts/BS_NSDPDisplayGenericDetails.aspx?Id=219
A44: NSE India — DIXON: https://www.nseindia.com/get-quotes/equity?symbol=DIXON

Sheet IS
A1: DIXON TECHNOLOGIES — INCOME STATEMENT (₹ Crore)
B2: FY22A | C2: FY23A | D2: FY24A | E2: FY25A | F2: FY26E | G2: FY27E | H2: FY28E | I2: FY29E | J2: FY30E
B3: Actual | C3: Actual | D3: Actual | E3: Actual | F3: Forecast | G3: Forecast | H3: Forecast | I3: Forecast | J3: Forecast
A4: REVENUE
A6: Net Revenue / Net Sales | B6: 10697 | C6: 12192 | D6: 17691 | E6: 38860 | F6: =E6*(1+ASSUMP!B5) | G6: =F6*(1+ASSUMP!B6) | H6: =G6*(1+ASSUMP!B7) | I6: =H6*(1+ASSUMP!B8) | J6: =I6*(1+ASSUMP!B9)
A7: YoY Revenue Growth % | C7: =C6/B6-1 | D7: =D6/C6-1 | E7: =E6/D6-1 | F7: =F6/E6-1 | G7: =G6/F6-1 | H7: =H6/G6-1 | I7: =I6/H6-1 | J7: =J6/I6-1
A8: COST STRUCTURE
A10: Raw Materials / COGS | B10: 9330 | C10: 10630 | D10: 15440 | E10: 34000 | F10: =F6-(ASSUMP!B10*F6)-(F6*0.025)-(F6*0.053) | G10: =G6-(ASSUMP!B10*G6)-(G6*0.025)-(G6*0.053) | H10: =H6-(ASSUMP!B10*H6)-(H6*0.025)-(H6*0.053) | I10: =I6-(ASSUMP!B10*I6)-(I6*0.025)-(I6*0.053) | J10: =J6-(ASSUMP!B10*J6)-(J6*0.025)-(J6*0.053)
A11: Employee Expenses | B11: 307 | C11: 360 | D11: 490 | E11: 950 | F11: =F6*0.025 | G11: =G6*0.025 | H11: =H6*0.025 | I11: =I6*0.025 | J11: =J6*0.025
A12: Other Operating Expenses | B12: 630 | C12: 692 | D12: 1053 | E12: 1967 | F12: =F6*0.053 | G12: =G6*0.053 | H12: =H6*0.053 | I12: =I6*0.053 | J12: =J6*0.053
A13: EBITDA | B13: =B6-B10-B11-B12 | C13: =C6-C10-C11-C12 | D13: =D6-D10-D11-D12 | E13: =E6-E10-E11-E12 | F13: =F6-F10-F11-F12 | G13: =G6-G10-G11-G12 | H13: =H6-H10-H11-H12 | I13: =I6-I10-I11-I12 | J13: =J6-J10-J11-J12
A14: EBITDA Margin % | B14: =B13/B6 | C14: =C13/C6 | D14: =D13/D6 | E14: =E13/E6 | F14: =F13/F6 | G14: =G13/G6 | H14: =H13/H6 | I14: =I13/I6 | J14: =J13/J6
A15: BELOW EBITDA
A17: Depreciation & Amortisation (D&A) | B17: 115 | C17: 140 | D17: 185 | E17: 280 | F17: =F6*ASSUMP!B11 | G17: =G6*ASSUMP!B11 | H17: =H6*ASSUMP!B11 | I17: =I6*ASSUMP!B11 | J17: =J6*ASSUMP!B11
A18: EBIT (Operating Profit) | B18: =B13-B17 | C18: =C13-C17 | D18: =D13-D17 | E18: =E13-E17 | F18: =F13-F17 | G18: =G13-G17 | H18: =H13-H17 | I18: =I13-I17 | J18: =J13-J17
A19: EBIT Margin % | B19: =B18/B6 | C19: =C18/C6 | D19: =D18/D6 | E19: =E18/E6 | F19: =F18/F6 | G19: =G18/G6 | H19: =H18/H6 | I19: =I18/I6 | J19: =J18/J6
A22: Interest Expense | B22: 35 | C22: 45 | D22: 85 | E22: 120 | F22: =ROUND((BS!E21+BS!E26)*ASSUMP!B13,0) | G22: =ROUND((BS!F21+BS!F26)*ASSUMP!B13,0) | H22: =ROUND((BS!G21+BS!G26)*ASSUMP!B13,0) | I22: =ROUND((BS!H21+BS!H26)*ASSUMP!B13,0) | J22: =ROUND((BS!I21+BS!I26)*ASSUMP!B13,0)
A23: Profit Before Tax (PBT) | B23: =B18-B22 | C23: =C18-C22 | D23: =D18-D22 | E23: =E18-E22 | F23: =F18-F22 | G23: =G18-G22 | H23: =H18-H22 | I23: =I18-I22 | J23: =J18-J22
A24: Tax Expense | B24: 68 | C24: 85 | D24: 108 | E24: 400 | F24: =F23*ASSUMP!B12 | G24: =G23*ASSUMP!B12 | H24: =H23*ASSUMP!B12 | I24: =I23*ASSUMP!B12 | J24: =J23*ASSUMP!B12
A25: Effective Tax Rate % | B25: =B24/B23 | C25: =C24/C23 | D25: =D24/D23 | E25: =E24/E23 | F25: =F24/F23 | G25: =G24/G23 | H25: =H24/H23 | I25: =I24/I23 | J25: =J24/J23
A26: Minority Interest (deduction) | B26: 19 | C26: 0 | D26: -37 | E26: -61 | F26: =-ROUND(F6*0.001,0) | G26: =-ROUND(G6*0.001,0) | H26: =-ROUND(H6*0.001,0) | I26: =-ROUND(I6*0.001,0) | J26: =-ROUND(J6*0.001,0)
A27: PAT (Profit After Tax) | B27: =B23-B24-B26 | C27: =C23-C24-C26 | D27: =D23-D24-D26 | E27: =E23-E24-E26 | F27: =F23-F24-F26 | G27: =G23-G24-G26 | H27: =H23-H24-H26 | I27: =I23-I24-I26 | J27: =J23-J24-J26
A28: PAT Margin % | B28: =B27/B6 | C28: =C27/C6 | D28: =D27/D6 | E28: =E27/E6 | F28: =F27/F6 | G28: =G27/G6 | H28: =H27/H6 | I28: =I27/I6 | J28: =J27/J6
A29: EPS (₹ per share) | B29: =B27*100/ASSUMP!B19 | C29: =C27*100/ASSUMP!B19 | D29: =D27*100/ASSUMP!B19 | E29: =E27*100/ASSUMP!B19 | F29: =F27*100/ASSUMP!B19 | G29: =G27*100/ASSUMP!B19 | H29: =H27*100/ASSUMP!B19 | I29: =I27*100/ASSUMP!B19 | J29: =J27*100/ASSUMP!B19
A32: RATIO ANALYSIS —— WiDS Week 1
A33: PROFITABILITY RATIOS
A34: Gross Margin (Revenue − COGS) / Revenue | B34: =(B6-B10)/B6 | C34: =(C6-C10)/C6 | D34: =(D6-D10)/D6 | E34: =(E6-E10)/E6 | F34: =(F6-F10)/F6 | G34: =(G6-G10)/G6 | H34: =(H6-H10)/H6 | I34: =(I6-I10)/I6 | J34: =(J6-J10)/J6
A35: EBITDA Margin % | B35: =B13/B6 | C35: =C13/C6 | D35: =D13/D6 | E35: =E13/E6 | F35: =F13/F6 | G35: =G13/G6 | H35: =H13/H6 | I35: =I13/I6 | J35: =J13/J6
A36: EBIT Margin % (Operating Margin) | B36: =B18/B6 | C36: =C18/C6 | D36: =D18/D6 | E36: =E18/E6 | F36: =F18/F6 | G36: =G18/G6 | H36: =H18/H6 | I36: =I18/I6 | J36: =J18/J6
A37: PAT Margin % (Net Profit Margin) | B37: =B27/B6 | C37: =C27/C6 | D37: =D27/D6 | E37: =E27/E6 | F37: =F27/F6 | G37: =G27/G6 | H37: =H27/H6 | I37: =I27/I6 | J37: =J27/J6
A38: Return on Equity (ROE) = PAT / Equity | B38: =B27/BS!B20 | C38: =C27/BS!C20 | D38: =D27/BS!D20 | E38: =E27/BS!E20 | F38: =F27/BS!F20 | G38: =G27/BS!G20 | H38: =H27/BS!H20 | I38: =I27/BS!I20 | J38: =J27/BS!J20
A39: Return on Assets (ROA) = PAT / Total Assets | B39: =B27/BS!B17 | C39: =C27/BS!C17 | D39: =D27/BS!D17 | E39: =E27/BS!E17 | F39: =F27/BS!F17 | G39: =G27/BS!G17 | H39: =H27/BS!H17 | I39: =I27/BS!I17 | J39: =J27/BS!J17
A40: ROCE = EBIT / (Total Assets − Current Liabilities) | B40: =B18/(BS!B17-BS!B28) | C40: =C18/(BS!C17-BS!C28) | D40: =D18/(BS!D17-BS!D28) | E40: =E18/(BS!E17-BS!E28) | F40: =F18/(BS!F17-BS!F28) | G40: =G18/(BS!G17-BS!G28) | H40: =H18/(BS!H17-BS!H28) | I40: =I18/(BS!I17-BS!I28) | J40: =J18/(BS!J17-BS!J28)
A42: EFFICIENCY / ACTIVITY RATIOS (days)
A43: Inventory Days (Inventory / COGS × 365) | B43: =BS!B12/B10*365 | C43: =BS!C12/C10*365 | D43: =BS!D12/D10*365 | E43: =BS!E12/E10*365 | F43: =BS!F12/F10*365 | G43: =BS!G12/G10*365 | H43: =BS!H12/H10*365 | I43: =BS!I12/I10*365 | J43: =BS!J12/J10*365
A44: Receivable Days (Trade Rec / Revenue × 365) | B44: =BS!B13/B6*365 | C44: =BS!C13/C6*365 | D44: =BS!D13/D6*365 | E44: =BS!E13/E6*365 | F44: =BS!F13/F6*365 | G44: =BS!G13/G6*365 | H44: =BS!H13/H6*365 | I44: =BS!I13/I6*365 | J44: =BS!J13/J6*365
A45: Payable Days (Trade Pay / COGS × 365) | B45: =BS!B25/B10*365 | C45: =BS!C25/C10*365 | D45: =BS!D25/D10*365 | E45: =BS!E25/E10*365 | F45: =BS!F25/F10*365 | G45: =BS!G25/G10*365 | H45: =BS!H25/H10*365 | I45: =BS!I25/I10*365 | J45: =BS!J25/J10*365
A46: Asset Turnover (Revenue / Total Assets) | B46: =B6/BS!B17 | C46: =C6/BS!C17 | D46: =D6/BS!D17 | E46: =E6/BS!E17 | F46: =F6/BS!F17 | G46: =G6/BS!G17 | H46: =H6/BS!H17 | I46: =I6/BS!I17 | J46: =J6/BS!J17
A48: LEVERAGE RATIOS
A49: Debt / Equity ((LT Debt + ST Debt) / Equity) | B49: =(BS!B21+BS!B26)/BS!B20 | C49: =(BS!C21+BS!C26)/BS!C20 | D49: =(BS!D21+BS!D26)/BS!D20 | E49: =(BS!E21+BS!E26)/BS!E20 | F49: =(BS!F21+BS!F26)/BS!F20 | G49: =(BS!G21+BS!G26)/BS!G20 | H49: =(BS!H21+BS!H26)/BS!H20 | I49: =(BS!I21+BS!I26)/BS!I20 | J49: =(BS!J21+BS!J26)/BS!J20
...

Sheet BS
A1: DIXON TECHNOLOGIES — BALANCE SHEET (₹ Crore)
B2: FY22A | C2: FY23A | D2: FY24A | E2: FY25A | F2: FY26E | G2: FY27E | H2: FY28E | I2: FY29E | J2: FY30E
B3: Actual | C3: Actual | D3: Actual | E3: Actual | F3: Forecast | G3: Forecast | H3: Forecast | I3: Forecast | J3: Forecast
A4: NON-CURRENT ASSETS
A6: Net Fixed Assets (PP&E, net) | B6: 720 | C6: 850 | D6: 1150 | E6: 1800 | F6: =E6+IS!F6*ASSUMP!B17-IS!F17 | G6: =F6+IS!G6*ASSUMP!B17-IS!G17 | H6: =G6+IS!H6*ASSUMP!B17-IS!H17 | I6: =H6+IS!I6*ASSUMP!B17-IS!I17 | J6: =I6+IS!J6*ASSUMP!B17-IS!J17
A7: Goodwill & Intangibles | B7: 80 | C7: 75 | D7: 70 | E7: 65 | F7: =E7*0.95 | G7: =F7*0.95 | H7: =G7*0.95 | I7: =H7*0.95 | J7: =I7*0.95
A8: Long-term Investments & Others | B8: 120 | C8: 140 | D8: 200 | E8: 380 | F8: =E8*1.08 | G8: =F8*1.08 | H8: =G8*1.08 | I8: =H8*1.08 | J8: =I8*1.08
A9: TOTAL NON-CURRENT ASSETS | B9: =B6+B7+B8 | C9: =C6+C7+C8 | D9: =D6+D7+D8 | E9: =E6+E7+E8 | F9: =F6+F7+F8 | G9: =G6+G7+G8 | H9: =H6+H7+H8 | I9: =I6+I7+I8 | J9: =J6+J7+J8
A10: CURRENT ASSETS
A12: Inventories | B12: 750 | C12: 900 | D12: 1400 | E12: 2800 | F12: =IS!F6*0.072 | G12: =IS!G6*0.072 | H12: =IS!H6*0.072 | I12: =IS!I6*0.072 | J12: =IS!J6*0.072
A13: Trade Receivables | B13: 900 | C13: 1100 | D13: 1750 | E13: 4200 | F13: =IS!F6*0.108 | G13: =IS!G6*0.108 | H13: =IS!H6*0.108 | I13: =IS!I6*0.108 | J13: =IS!J6*0.108
A14: Cash & Cash Equivalents | B14: 320 | C14: 290 | D14: 450 | E14: 1200 | F14: =E14+CF!F22 | G14: =F14+CF!G22 | H14: =G14+CF!H22 | I14: =H14+CF!I22 | J14: =I14+CF!J22
A15: Other Current Assets | B15: 450 | C15: 520 | D15: 750 | E15: 1500 | F15: =IS!F6*0.039 | G15: =IS!G6*0.039 | H15: =IS!H6*0.039 | I15: =IS!I6*0.039 | J15: =IS!J6*0.039
A16: TOTAL CURRENT ASSETS | B16: =B12+B13+B14+B15 | C16: =C12+C13+C14+C15 | D16: =D12+D13+D14+D15 | E16: =E12+E13+E14+E15 | F16: =F12+F13+F14+F15 | G16: =G12+G13+G14+G15 | H16: =H12+H13+H14+H15 | I16: =I12+I13+I14+I15 | J16: =J12+J13+J14+J15
A17: TOTAL ASSETS | B17: =B9+B16 | C17: =C9+C16 | D17: =D9+D16 | E17: =E9+E16 | F17: =F9+F16 | G17: =G9+G16 | H17: =H9+H16 | I17: =I9+I16 | J17: =J9+J16
A18: EQUITY & LIABILITIES
A20: Shareholders' Equity | B20: 1100 | C20: 1350 | D20: 1720 | E20: 2940 | F20: =E20+IS!F27+CF!F19 | G20: =F20+IS!G27+CF!G19 | H20: =G20+IS!H27+CF!H19 | I20: =H20+IS!I27+CF!I19 | J20: =I20+IS!J27+CF!J19
A21: Long-term Borrowings (LT Debt) | B21: 180 | C21: 220 | D21: 350 | E21: 600 | F21: =E21*1.05 | G21: =F21*1.05 | H21: =G21*1.05 | I21: =H21*1.05 | J21: =I21*1.05
A22: Deferred Tax & Other NCL | B22: 80 | C22: 90 | D22: 120 | E22: 180 | F22: =E22*1.04 | G22: =F22*1.04 | H22: =G22*1.04 | I22: =H22*1.04 | J22: =I22*1.04
A23: CURRENT LIABILITIES
A25: Trade Payables | B25: 900 | C25: 1050 | D25: 1600 | E25: 3800 | F25: =IS!F10*0.112 | G25: =IS!G10*0.112 | H25: =IS!H10*0.112 | I25: =IS!I10*0.112 | J25: =IS!J10*0.112
A26: Short-term Borrowings (ST Debt) | B26: 250 | C26: 300 | D26: 420 | E26: 500 | F26: =E26*0.95 | G26: =F26*0.95 | H26: =G26*0.95 | I26: =H26*0.95 | J26: =I26*0.95
A27: Other Current Liabilities | B27: 600 | C27: 720 | D27: 1100 | E27: 2600 | F27: =IS!F6*0.067 | G27: =IS!G6*0.067 | H27: =IS!H6*0.067 | I27: =IS!I6*0.067 | J27: =IS!J6*0.067
A28: TOTAL CURRENT LIABILITIES | B28: =B25+B26+B27 | C28: =C25+C26+C27 | D28: =D25+D26+D27 | E28: =E25+E26+E27 | F28: =F25+F26+F27 | G28: =G25+G26+G27 | H28: =H25+H26+H27 | I28: =I25+I26+I27 | J28: =J25+J26+J27
A29: TOTAL EQUITY & LIABILITIES | B29: =B20+B21+B22+B28 | C29: =C20+C21+C22+C28 | D29: =D20+D21+D22+D28 | E29: =E20+E21+E22+E28 | F29: =F20+F21+F22+F28 | G29: =G20+G21+G22+G28 | H29: =H20+H21+H22+H28 | I29: =I20+I21+I22+I28 | J29: =J20+J21+J22+J28
A30: ✔ Balance Check (Assets − L&E = 0?) | B30: =B17-B29 | C30: =C17-C29 | D30: =D17-D29 | E30: =E17-E29 | F30: =F17-F29 | G30: =G17-G29 | H30: =H17-H29 | I30: =I17-I29 | J30: =J17-J29

Sheet CF
A1: DIXON TECHNOLOGIES — CASH FLOW STATEMENT (₹ Crore, Indirect Method)
B2: FY22A | C2: FY23A | D2: FY24A | E2: FY25A | F2: FY26E | G2: FY27E | H2: FY28E | I2: FY29E | J2: FY30E
B3: Actual | C3: Actual | D3: Actual | E3: Actual | F3: Forecast | G3: Forecast | H3: Forecast | I3: Forecast | J3: Forecast
A4: OPERATING ACTIVITIES
A5: Net Profit (PAT) | B5: =IS!B27 | C5: =IS!C27 | D5: =IS!D27 | E5: =IS!E27 | F5: =IS!F27 | G5: =IS!G27 | H5: =IS!H27 | I5: =IS!I27 | J5: =IS!J27
A6: Add: D&A (Non-cash) | B6: =IS!B17 | C6: =IS!C17 | D6: =IS!D17 | E6: =IS!E17 | F6: =IS!F17 | G6: =IS!G17 | H6: =IS!H17 | I6: =IS!I17 | J6: =IS!J17
A7: Changes in Working Capital (ΔNWC) | B7: -120 | C7: -180 | D7: -320 | E7: -950 | F7: =-(IS!F6-IS!E6)*ASSUMP!B18 | G7: =-(IS!G6-IS!F6)*ASSUMP!B18 | H7: =-(IS!H6-IS!G6)*ASSUMP!B18 | I7: =-(IS!I6-IS!H6)*ASSUMP!B18 | J7: =-(IS!J6-IS!I6)*ASSUMP!B18
A8: Other Adjustments (Interest & Tax paid) | B8: -30 | C8: -40 | D8: -75 | E8: -110 | F8: =-(IS!F22+IS!F24)*0.05 | G8: =-(IS!G22+IS!G24)*0.05 | H8: =-(IS!H22+IS!H24)*0.05 | I8: =-(IS!I22+IS!I24)*0.05 | J8: =-(IS!J22+IS!J24)*0.05
A9: CASH FROM OPERATIONS (CFO) | B9: =B5+B6+B7+B8 | C9: =C5+C6+C7+C8 | D9: =D5+D6+D7+D8 | E9: =E5+E6+E7+E8 | F9: =F5+F6+F7+F8 | G9: =G5+G6+G7+G8 | H9: =H5+H6+H7+H8 | I9: =I5+I6+I7+I8 | J9: =J5+J6+J7+J8
A11: INVESTING ACTIVITIES
A12: Capital Expenditure (Capex) | B12: -155 | C12: -195 | D12: -340 | E12: -600 | F12: =-(IS!F6*ASSUMP!B17) | G12: =-(IS!G6*ASSUMP!B17) | H12: =-(IS!H6*ASSUMP!B17) | I12: =-(IS!I6*ASSUMP!B17) | J12: =-(IS!J6*ASSUMP!B17)
A13: Investments & Others | B13: -40 | C13: -25 | D13: -65 | E13: -180 | F13: =-IS!F6*0.005 | G13: =-IS!G6*0.005 | H13: =-IS!H6*0.005 | I13: =-IS!I6*0.005 | J13: =-IS!J6*0.005
A14: CASH FROM INVESTING (CFI) | B14: =B12+B13 | C14: =C12+C13 | D14: =D12+D13 | E14: =E12+E13 | F14: =F12+F13 | G14: =G12+G13 | H14: =H12+H13 | I14: =I12+I13 | J14: =J12+J13
A16: FINANCING ACTIVITIES
A17: Proceeds from / (Repayment of) Debt | B17: 80 | C17: 60 | D17: 120 | E17: 80 | F17: =IS!F6*0.002 | G17: =IS!G6*0.002 | H17: =IS!H6*0.002 | I17: =IS!I6*0.002 | J17: =IS!J6*0.002
A18: Interest Paid | B18: =-IS!B22 | C18: =-IS!C22 | D18: =-IS!D22 | E18: =-IS!E22 | F18: =-IS!F22 | G18: =-IS!G22 | H18: =-IS!H22 | I18: =-IS!I22 | J18: =-IS!J22
A19: Dividends Paid | B19: -18 | C19: -22 | D19: -28 | E19: -60 | F19: =-IS!F27*0.08 | G19: =-IS!G27*0.08 | H19: =-IS!H27*0.08 | I19: =-IS!I27*0.08 | J19: =-IS!J27*0.08
A20: CASH FROM FINANCING (CFF) | B20: =B17+B18+B19 | C20: =C17+C18+C19 | D20: =D17+D18+D19 | E20: =E17+E18+E19 | F20: =F17+F18+F19 | G20: =G17+G18+G19 | H20: =H17+H18+H19 | I20: =I17+I18+I19 | J20: =J17+J18+J19
A22: NET CHANGE IN CASH (CFO + CFI + CFF) | B22: =B9+B14+B20 | C22: =C9+C14+C20 | D22: =D9+D14+D20 | E22: =E9+E14+E20 | F22: =F9+F14+F20 | G22: =G9+G14+G20 | H22: =H9+H14+H20 | I22: =I9+I14+I20 | J22: =J9+J14+J20
A23: Opening Cash Balance | C23: 320 | D23: 290 | E23: 450 | F23: =BS!E14 | G23: =BS!F14 | H23: =BS!G14 | I23: =BS!H14 | J23: =BS!I14
A24: Closing Cash Balance | B24: =B23+B22 | C24: =C23+C22 | D24: =D23+D22 | E24: =E23+E22 | F24: =F23+F22 | G24: =G23+G22 | H24: =H23+H22 | I24: =I23+I22 | J24: =J23+J22

Sheet DCF
A1: DIXON TECHNOLOGIES — DCF VALUATION + WACC (₹ Crore)
A3: SECTION A — WACC DERIVATION (WiDS Week 3 — CAPM)
A4: Parameter | B4: Value | C4: Notes
A5: Risk-Free Rate (Rf) | B5: =ASSUMP!B24 | C5: India 10-yr G-Sec yield — RBI (June 2026)
A6: Equity Risk Premium (ERP) | B6: =ASSUMP!B25 | C6: Damodaran India ERP (Jan 2026)
A7: Beta (β) — Levered vs Nifty 50 | B7: =ASSUMP!B26 | C7: Regressed 2-yr weekly; EMS is cyclical
A8: Cost of Equity Ke = Rf + β×ERP | B8: =ASSUMP!B27 | C8: CAPM: 7.0% + 1.40 × 6.0% = 15.4%
A9: Weight of Debt D/(D+E) | B9: =ASSUMP!B28 | C9: Conservative; Dixon equity-heavy per FY25 BS
A10: Pre-tax Cost of Debt Kd | B10: =ASSUMP!B29 | C10: Repo + ~200bps spread
A11: After-tax Cost of Debt Kd×(1-t) | B11: =ASSUMP!B30 | C11: Tax shield on interest
A12: Weight of Equity E/(D+E) | B12: =1-ASSUMP!B28 | C12: Complement of debt weight
A13: Terminal Growth Rate (g) | B13: =ASSUMP!B35 | C13: Long-run India nominal GDP growth proxy
A15: ► WACC = Ke×(E%) + Kd×(D%) | B15: =ASSUMP!B31 | C15: ≈ 13.6% | Ke×80% + Kd_at×20%
A18: SECTION B — FREE CASH FLOW TO FIRM (FCFF) FY26E–FY30E
C19: FY26E | D19: FY27E | E19: FY28E | F19: FY29E | G19: FY30E
A20: Revenue (₹ Cr) | C20: =IS!F6 | D20: =IS!G6 | E20: =IS!H6 | F20: =IS!I6 | G20: =IS!J6
A21: EBIT (₹ Cr) | C21: =IS!F18 | D21: =IS!G18 | E21: =IS!H18 | F21: =IS!I18 | G21: =IS!J18
A22: EBIT Margin % | C22: =IS!F19 | D22: =IS!G19 | E22: =IS!H19 | F22: =IS!I19 | G22: =IS!J19
A23: Tax Rate | C23: =ASSUMP!B12 | D23: =ASSUMP!B12 | E23: =ASSUMP!B12 | F23: =ASSUMP!B12 | G23: =ASSUMP!B12
A24: NOPAT = EBIT × (1 − Tax Rate) | C24: =C21*(1-ASSUMP!B12) | D24: =D21*(1-ASSUMP!B12) | E24: =E21*(1-ASSUMP!B12) | F24: =F21*(1-ASSUMP!B12) | G24: =G21*(1-ASSUMP!B12)
A25: Add: D&A | C25: =IS!F17 | D25: =IS!G17 | E25: =IS!H17 | F25: =IS!I17 | G25: =IS!J17
A26: Less: Capex | C26: =-(IS!F6*ASSUMP!B17) | D26: =-(IS!G6*ASSUMP!B17) | E26: =-(IS!H6*ASSUMP!B17) | F26: =-(IS!I6*ASSUMP!B17) | G26: =-(IS!J6*ASSUMP!B17)
A27: FCFF = NOPAT + D&A − Capex − ΔNWC | C27: =C24+C25+C26+C28 | D27: =D24+D25+D26+D28 | E27: =E24+E25+E26+E28 | F27: =F24+F25+F26+F28 | G27: =G24+G25+G26+G28
A28: Less: ΔNWC (Change in Net Working Capital) | C28: =-(IS!F6*ASSUMP!B18-IS!E6*ASSUMP!B18) | D28: =-(IS!G6*ASSUMP!B18-IS!F6*ASSUMP!B18) | E28: =-(IS!H6*ASSUMP!B18-IS!G6*ASSUMP!B18) | F28: =-(IS!I6*ASSUMP!B18-IS!H6*ASSUMP!B18) | G28: =-(IS!J6*ASSUMP!B18-IS!I6*ASSUMP!B18)
A31: SECTION C — PRESENT VALUE OF FCFF
C32: FY26E | D32: FY27E | E32: FY28E | F32: FY29E | G32: FY30E
A33: Discount Period (t) | C33: 1 | D33: 2 | E33: 3 | F33: 4 | G33: 5
A34: Discount Factor = 1 / (1+WACC)^t | C34: =1/(1+ASSUMP!B31)^C33 | D34: =1/(1+ASSUMP!B31)^D33 | E34: =1/(1+ASSUMP!B31)^E33 | F34: =1/(1+ASSUMP!B31)^F33 | G34: =1/(1+ASSUMP!B31)^G33
A35: PV of FCFF | C35: =C27*C34 | D35: =D27*D34 | E35: =E27*E34 | F35: =F27*F34 | G35: =G27*G34
A38: SECTION D — TERMINAL VALUE (Gordon Growth Model)
A39: Terminal Year FCFF (FY30E) | C39: =G27
A40: Terminal Growth Rate (g) | C40: =ASSUMP!B35
A41: WACC | C41: =ASSUMP!B31
A42: Terminal Value = FCFF×(1+g) / (WACC − g) | C42: =C39*(1+ASSUMP!B35)/(ASSUMP!B31-ASSUMP!B35)
A43: PV of Terminal Value = TV / (1+WACC)^5 | C43: =C42/(1+ASSUMP!B31)^5
A46: SECTION E — ENTERPRISE VALUE → EQUITY VALUE BRIDGE
A47: Sum of PV (FCFF) — FY26–FY30 | C47: =SUM(C35:G35)
A48: PV of Terminal Value | C48: =C43
A49: Enterprise Value (EV) | C49: =C47+C48
A51: Less: Total Debt (LT + ST) | C51: =-(BS!E21+BS!E26)
...

Sheet SENSITIVITY
A1: DIXON TECHNOLOGIES — 2-WAY SENSITIVITY | Implied Share Price (₹)
B3: Implied Share Price (₹) sensitised across WACC (rows) and Terminal Growth Rate (columns). Formula replicates full DCF inline — no circular references.
B5: WACC ↓ / TGR → | C5: 0.04 | D5: 0.045 | E5: 0.05 | F5: 0.055 | G5: 0.06 | H5: 0.065 | I5: 0.07
B6: 0.11 | C6: =IF(C5>=B6,"N/A",(DCF!C27/(1+B6)^1+DCF!D27/(1+B6)^2+DCF!E27/(1+B6)^3+DCF!F27/(1+B6)^4+DCF!G27/(1+B6)^5+DCF!G27*(1+C5)/(B6-C5)/(1+B6)^5+DCF!C51+DCF!C52+DCF!C53)*100/ASSUMP!B19) | D6: =IF(D5>=B6,"N/A",(DCF!C27/(1+B6)^1+DCF!D27/(1+B6)^2+DCF!E27/(1+B6)^3+DCF!F27/(1+B6)^4+DCF!G27/(1+B6)^5+DCF!G27*(1+D5)/(B6-D5)/(1+B6)^5+DCF!C51+DCF!C52+DCF!C53)*100/ASSUMP!B19) | E6: =IF(E5>=B6,"N/A",(DCF!C27/(1+B6)^1+DCF!D27/(1+B6)^2+DCF!E27/(1+B6)^3+DCF!F27/(1+B6)^4+DCF!G27/(1+B6)^5+DCF!G27*(1+E5)/(B6-E5)/(1+B6)^5+DCF!C51+DCF!C52+DCF!C53)*100/ASSUMP!B19) | F6: =IF(F5>=B6,"N/A",(DCF!C27/(1+B6)^1+DCF!D27/(1+B6)^2+DCF!E27/(1+B6)^3+DCF!F27/(1+B6)^4+DCF!G27/(1+B6)^5+DCF!G27*(1+F5)/(B6-F5)/(1+B6)^5+DCF!C51+DCF!C52+DCF!C53)*100/ASSUMP!B19) | G6: =IF(G5>=B6,"N/A",(DCF!C27/(1+B6)^1+DCF!D27/(1+B6)^2+DCF!E27/(1+B6)^3+DCF!F27/(1+B6)^4+DCF!G27/(1+B6)^5+DCF!G27*(1+G5)/(B6-G5)/(1+B6)^5+DCF!C51+DCF!C52+DCF!C53)*100/ASSUMP!B19) | H6: =IF(H5>=B6,"N/A",(DCF!C27/(1+B6)^1+DCF!D27/(1+B6)^2+DCF!E27/(1+B6)^3+DCF!F27/(1+B6)^4+DCF!G27/(1+B6)^5+DCF!G27*(1+H5)/(B6-H5)/(1+B6)^5+DCF!C51+DCF!C52+DCF!C53)*100/ASSUMP!B19) | I6: =IF(I5>=B6,"N/A",(DCF!C27/(1+B6)^1+DCF!D27/(1+B6)^2+DCF!E27/(1+B6)^3+DCF!F27/(1+B6)^4+DCF!G27/(1+B6)^5+DCF!G27*(1+I5)/(B6-I5)/(1+B6)^5+DCF!C51+DCF!C52+DCF!C53)*100/ASSUMP!B19)
B7: 0.12 | C7: =IF(C5>=B7,"N/A",(DCF!C27/(1+B7)^1+DCF!D27/(1+B7)^2+DCF!E27/(1+B7)^3+DCF!F27/(1+B7)^4+DCF!G27/(1+B7)^5+DCF!G27*(1+C5)/(B7-C5)/(1+B7)^5+DCF!C51+DCF!C52+DCF!C53)*100/ASSUMP!B19) | D7: =IF(D5>=B7,"N/A",(DCF!C27/(1+B7)^1+DCF!D27/(1+B7)^2+DCF!E27/(1+B7)^3+DCF!F27/(1+B7)^4+DCF!G27/(1+B7)^5+DCF!G27*(1+D5)/(B7-D5)/(1+B7)^5+DCF!C51+DCF!C52+DCF!C53)*100/ASSUMP!B19) | E7: =IF(E5>=B7,"N/A",(DCF!C27/(1+B7)^1+DCF!D27/(1+B7)^2+DCF!E27/(1+B7)^3+DCF!F27/(1+B7)^4+DCF!G27/(1+B7)^5+DCF!G27*(1+E5)/(B7-E5)/(1+B7)^5+DCF!C51+DCF!C52+DCF!C53)*100/ASSUMP!B19) | F7: =IF(F5>=B7,"N/A",(DCF!C27/(1+B7)^1+DCF!D27/(1+B7)^2+DCF!E27/(1+B7)^3+DCF!F27/(1+B7)^4+DCF!G27/(1+B7)^5+DCF!G27*(1+F5)/(B7-F5)/(1+B7)^5+DCF!C51+DCF!C52+DCF!C53)*100/ASSUMP!B19) | G7: =IF(G5>=B7,"N/A",(DCF!C27/(1+B7)^1+DCF!D27/(1+B7)^2+DCF!E27/(1+B7)^3+DCF!F27/(1+B7)^4+DCF!G27/(1+B7)^5+DCF!G27*(1+G5)/(B7-G5)/(1+B7)^5+DCF!C51+DCF!C52+DCF!C53)*100/ASSUMP!B19) | H7: =IF(H5>=B7,"N/A",(DCF!C27/(1+B7)^1+DCF!D27/(1+B7)^2+DCF!E27/(1+B7)^3+DCF!F27/(1+B7)^4+DCF!G27/(1+B7)^5+DCF!G27*(1+H5)/(B7-H5)/(1+B7)^5+DCF!C51+DCF!C52+DCF!C53)*100/ASSUMP!B19) | I7: =IF(I5>=B7,"N/A",(DCF!C27/(1+B7)^1+DCF!D27/(1+B7)^2+DCF!E27/(1+B7)^3+DCF!F27/(1+B7)^4+DCF!G27/(1+B7)^5+DCF!G27*(1+I5)/(B7-I5)/(1+B7)^5+DCF!C51+DCF!C52+DCF!C53)*100/ASSUMP!B19)
B8: 0.13 | C8: =IF(C5>=B8,"N/A",(DCF!C27/(1+B8)^1+DCF!D27/(1+B8)^2+DCF!E27/(1+B8)^3+DCF!F27/(1+B8)^4+DCF!G27/(1+B8)^5+DCF!G27*(1+C5)/(B8-C5)/(1+B8)^5+DCF!C51+DCF!C52+DCF!C53)*100/ASSUMP!B19) | D8: =IF(D5>=B8,"N/A",(DCF!C27/(1+B8)^1+DCF!D27/(1+B8)^2+DCF!E27/(1+B8)^3+DCF!F27/(1+B8)^4+DCF!G27/(1+B8)^5+DCF!G27*(1+D5)/(B8-D5)/(1+B8)^5+DCF!C51+DCF!C52+DCF!C53)*100/ASSUMP!B19) | E8: =IF(E5>=B8,"N/A",(DCF!C27/(1+B8)^1+DCF!D27/(1+B8)^2+DCF!E27/(1+B8)^3+DCF!F27/(1+B8)^4+DCF!G27/(1+B8)^5+DCF!G27*(1+E5)/(B8-E5)/(1+B8)^5+DCF!C51+DCF!C52+DCF!C53)*100/ASSUMP!B19) | F8: =IF(F5>=B8,"N/A",(DCF!C27/(1+B8)^1+DCF!D27/(1+B8)^2+DCF!E27/(1+B8)^3+DCF!F27/(1+B8)^4+DCF!G27/(1+B8)^5+DCF!G27*(1+F5)/(B8-F5)/(1+B8)^5+DCF!C51+DCF!C52+DCF!C53)*100/ASSUMP!B19) | G8: =IF(G5>=B8,"N/A",(DCF!C27/(1+B8)^1+DCF!D27/(1+B8)^2+DCF!E27/(1+B8)^3+DCF!F27/(1+B8)^4+DCF!G27/(1+B8)^5+DCF!G27*(1+G5)/(B8-G5)/(1+B8)^5+DCF!C51+DCF!C52+DCF!C53)*100/ASSUMP!B19) | H8: =IF(H5>=B8,"N/A",(DCF!C27/(1+B8)^1+DCF!D27/(1+B8)^2+DCF!E27/(1+B8)^3+DCF!F27/(1+B8)^4+DCF!G27/(1+B8)^5+DCF!G27*(1+H5)/(B8-H5)/(1+B8)^5+DCF!C51+DCF!C52+DCF!C53)*100/ASSUMP!B19) | I8: =IF(I5>=B8,"N/A",(DCF!C27/(1+B8)^1+DCF!D27/(1+B8)^2+DCF!E27/(1+B8)^3+DCF!F27/(1+B8)^4+DCF!G27/(1+B8)^5+DCF!G27*(1+I5)/(B8-I5)/(1+B8)^5+DCF!C51+DCF!C52+DCF!C53)*100/ASSUMP!B19)
B9: 0.136 | C9: =IF(C5>=B9,"N/A",(DCF!C27/(1+B9)^1+DCF!D27/(1+B9)^2+DCF!E27/(1+B9)^3+DCF!F27/(1+B9)^4+DCF!G27/(1+B9)^5+DCF!G27*(1+C5)/(B9-C5)/(1+B9)^5+DCF!C51+DCF!C52+DCF!C53)*100/ASSUMP!B19) | D9: =IF(D5>=B9,"N/A",(DCF!C27/(1+B9)^1+DCF!D27/(1+B9)^2+DCF!E27/(1+B9)^3+DCF!F27/(1+B9)^4+DCF!G27/(1+B9)^5+DCF!G27*(1+D5)/(B9-D5)/(1+B9)^5+DCF!C51+DCF!C52+DCF!C53)*100/ASSUMP!B19) | E9: =IF(E5>=B9,"N/A",(DCF!C27/(1+B9)^1+DCF!D27/(1+B9)^2+DCF!E27/(1+B9)^3+DCF!F27/(1+B9)^4+DCF!G27/(1+B9)^5+DCF!G27*(1+E5)/(B9-E5)/(1+B9)^5+DCF!C51+DCF!C52+DCF!C53)*100/ASSUMP!B19) | F9: =IF(F5>=B9,"N/A",(DCF!C27/(1+B9)^1+DCF!D27/(1+B9)^2+DCF!E27/(1+B9)^3+DCF!F27/(1+B9)^4+DCF!G27/(1+B9)^5+DCF!G27*(1+F5)/(B9-F5)/(1+B9)^5+DCF!C51+DCF!C52+DCF!C53)*100/ASSUMP!B19) | G9: =IF(G5>=B9,"N/A",(DCF!C27/(1+B9)^1+DCF!D27/(1+B9)^2+DCF!E27/(1+B9)^3+DCF!F27/(1+B9)^4+DCF!G27/(1+B9)^5+DCF!G27*(1+G5)/(B9-G5)/(1+B9)^5+DCF!C51+DCF!C52+DCF!C53)*100/ASSUMP!B19) | H9: =IF(H5>=B9,"N/A",(DCF!C27/(1+B9)^1+DCF!D27/(1+B9)^2+DCF!E27/(1+B9)^3+DCF!F27/(1+B9)^4+DCF!G27/(1+B9)^5+DCF!G27*(1+H5)/(B9-H5)/(1+B9)^5+DCF!C51+DCF!C52+DCF!C53)*100/ASSUMP!B19) | I9: =IF(I5>=B9,"N/A",(DCF!C27/(1+B9)^1+DCF!D27/(1+B9)^2+DCF!E27/(1+B9)^3+DCF!F27/(1+B9)^4+DCF!G27/(1+B9)^5+DCF!G27*(1+I5)/(B9-I5)/(1+B9)^5+DCF!C51+DCF!C52+DCF!C53)*100/ASSUMP!B19)
B10: 0.14 | C10: =IF(C5>=B10,"N/A",(DCF!C27/(1+B10)^1+DCF!D27/(1+B10)^2+DCF!E27/(1+B10)^3+DCF!F27/(1+B10)^4+DCF!G27/(1+B10)^5+DCF!G27*(1+C5)/(B10-C5)/(1+B10)^5+DCF!C51+DCF!C52+DCF!C53)*100/ASSUMP!B19) | D10: =IF(D5>=B10,"N/A",(DCF!C27/(1+B10)^1+DCF!D27/(1+B10)^2+DCF!E27/(1+B10)^3+DCF!F27/(1+B10)^4+DCF!G27/(1+B10)^5+DCF!G27*(1+D5)/(B10-D5)/(1+B10)^5+DCF!C51+DCF!C52+DCF!C53)*100/ASSUMP!B19) | E10: =IF(E5>=B10,"N/A",(DCF!C27/(1+B10)^1+DCF!D27/(1+B10)^2+DCF!E27/(1+B10)^3+DCF!F27/(1+B10)^4+DCF!G27/(1+B10)^5+DCF!G27*(1+E5)/(B10-E5)/(1+B10)^5+DCF!C51+DCF!C52+DCF!C53)*100/ASSUMP!B19) | F10: =IF(F5>=B10,"N/A",(DCF!C27/(1+B10)^1+DCF!D27/(1+B10)^2+DCF!E27/(1+B10)^3+DCF!F27/(1+B10)^4+DCF!G27/(1+B10)^5+DCF!G27*(1+F5)/(B10-F5)/(1+B10)^5+DCF!C51+DCF!C52+DCF!C53)*100/ASSUMP!B19) | G10: =IF(G5>=B10,"N/A",(DCF!C27/(1+B10)^1+DCF!D27/(1+B10)^2+DCF!E27/(1+B10)^3+DCF!F27/(1+B10)^4+DCF!G27/(1+B10)^5+DCF!G27*(1+G5)/(B10-G5)/(1+B10)^5+DCF!C51+DCF!C52+DCF!C53)*100/ASSUMP!B19) | H10: =IF(H5>=B10,"N/A",(DCF!C27/(1+B10)^1+DCF!D27/(1+B10)^2+DCF!E27/(1+B10)^3+DCF!F27/(1+B10)^4+DCF!G27/(1+B10)^5+DCF!G27*(1+H5)/(B10-H5)/(1+B10)^5+DCF!C51+DCF!C52+DCF!C53)*100/ASSUMP!B19) | I10: =IF(I5>=B10,"N/A",(DCF!C27/(1+B10)^1+DCF!D27/(1+B10)^2+DCF!E27/(1+B10)^3+DCF!F27/(1+B10)^4+DCF!G27/(1+B10)^5+DCF!G27*(1+I5)/(B10-I5)/(1+B10)^5+DCF!C51+DCF!C52+DCF!C53)*100/ASSUMP!B19)
B11: 0.15 | C11: =IF(C5>=B11,"N/A",(DCF!C27/(1+B11)^1+DCF!D27/(1+B11)^2+DCF!E27/(1+B11)^3+DCF!F27/(1+B11)^4+DCF!G27/(1+B11)^5+DCF!G27*(1+C5)/(B11-C5)/(1+B11)^5+DCF!C51+DCF!C52+DCF!C53)*100/ASSUMP!B19) | D11: =IF(D5>=B11,"N/A",(DCF!C27/(1+B11)^1+DCF!D27/(1+B11)^2+DCF!E27/(1+B11)^3+DCF!F27/(1+B11)^4+DCF!G27/(1+B11)^5+DCF!G27*(1+D5)/(B11-D5)/(1+B11)^5+DCF!C51+DCF!C52+DCF!C53)*100/ASSUMP!B19) | E11: =IF(E5>=B11,"N/A",(DCF!C27/(1+B11)^1+DCF!D27/(1+B11)^2+DCF!E27/(1+B11)^3+DCF!F27/(1+B11)^4+DCF!G27/(1+B11)^5+DCF!G27*(1+E5)/(B11-E5)/(1+B11)^5+DCF!C51+DCF!C52+DCF!C53)*100/ASSUMP!B19) | F11: =IF(F5>=B11,"N/A",(DCF!C27/(1+B11)^1+DCF!D27/(1+B11)^2+DCF!E27/(1+B11)^3+DCF!F27/(1+B11)^4+DCF!G27/(1+B11)^5+DCF!G27*(1+F5)/(B11-F5)/(1+B11)^5+DCF!C51+DCF!C52+DCF!C53)*100/ASSUMP!B19) | G11: =IF(G5>=B11,"N/A",(DCF!C27/(1+B11)^1+DCF!D27/(1+B11)^2+DCF!E27/(1+B11)^3+DCF!F27/(1+B11)^4+DCF!G27/(1+B11)^5+DCF!G27*(1+G5)/(B11-G5)/(1+B11)^5+DCF!C51+DCF!C52+DCF!C53)*100/ASSUMP!B19) | H11: =IF(H5>=B11,"N/A",(DCF!C27/(1+B11)^1+DCF!D27/(1+B11)^2+DCF!E27/(1+B11)^3+DCF!F27/(1+B11)^4+DCF!G27/(1+B11)^5+DCF!G27*(1+H5)/(B11-H5)/(1+B11)^5+DCF!C51+DCF!C52+DCF!C53)*100/ASSUMP!B19) | I11: =IF(I5>=B11,"N/A",(DCF!C27/(1+B11)^1+DCF!D27/(1+B11)^2+DCF!E27/(1+B11)^3+DCF!F27/(1+B11)^4+DCF!G27/(1+B11)^5+DCF!G27*(1+I5)/(B11-I5)/(1+B11)^5+DCF!C51+DCF!C52+DCF!C53)*100/ASSUMP!B19)
B12: 0.16 | C12: =IF(C5>=B12,"N/A",(DCF!C27/(1+B12)^1+DCF!D27/(1+B12)^2+DCF!E27/(1+B12)^3+DCF!F27/(1+B12)^4+DCF!G27/(1+B12)^5+DCF!G27*(1+C5)/(B12-C5)/(1+B12)^5+DCF!C51+DCF!C52+DCF!C53)*100/ASSUMP!B19) | D12: =IF(D5>=B12,"N/A",(DCF!C27/(1+B12)^1+DCF!D27/(1+B12)^2+DCF!E27/(1+B12)^3+DCF!F27/(1+B12)^4+DCF!G27/(1+B12)^5+DCF!G27*(1+D5)/(B12-D5)/(1+B12)^5+DCF!C51+DCF!C52+DCF!C53)*100/ASSUMP!B19) | E12: =IF(E5>=B12,"N/A",(DCF!C27/(1+B12)^1+DCF!D27/(1+B12)^2+DCF!E27/(1+B12)^3+DCF!F27/(1+B12)^4+DCF!G27/(1+B12)^5+DCF!G27*(1+E5)/(B12-E5)/(1+B12)^5+DCF!C51+DCF!C52+DCF!C53)*100/ASSUMP!B19) | F12: =IF(F5>=B12,"N/A",(DCF!C27/(1+B12)^1+DCF!D27/(1+B12)^2+DCF!E27/(1+B12)^3+DCF!F27/(1+B12)^4+DCF!G27/(1+B12)^5+DCF!G27*(1+F5)/(B12-F5)/(1+B12)^5+DCF!C51+DCF!C52+DCF!C53)*100/ASSUMP!B19) | G12: =IF(G5>=B12,"N/A",(DCF!C27/(1+B12)^1+DCF!D27/(1+B12)^2+DCF!E27/(1+B12)^3+DCF!F27/(1+B12)^4+DCF!G27/(1+B12)^5+DCF!G27*(1+G5)/(B12-G5)/(1+B12)^5+DCF!C51+DCF!C52+DCF!C53)*100/ASSUMP!B19) | H12: =IF(H5>=B12,"N/A",(DCF!C27/(1+B12)^1+DCF!D27/(1+B12)^2+DCF!E27/(1+B12)^3+DCF!F27/(1+B12)^4+DCF!G27/(1+B12)^5+DCF!G27*(1+H5)/(B12-H5)/(1+B12)^5+DCF!C51+DCF!C52+DCF!C53)*100/ASSUMP!B19) | I12: =IF(I5>=B12,"N/A",(DCF!C27/(1+B12)^1+DCF!D27/(1+B12)^2+DCF!E27/(1+B12)^3+DCF!F27/(1+B12)^4+DCF!G27/(1+B12)^5+DCF!G27*(1+I5)/(B12-I5)/(1+B12)^5+DCF!C51+DCF!C52+DCF!C53)*100/ASSUMP!B19)
B15: ★ Yellow cell = Base Case (WACC=13.6%, TGR=5.5%). N/A = mathematically undefined when TGR ≥ WACC (Gordon Growth Model constraint).

Sheet COMPS
A1: DIXON TECHNOLOGIES — PEER COMPARABLES | EMS / Electronics Manufacturing India (FY25A, ₹ Cr)
A3: Sources: BSE/NSE filings, Screener.in, Trendlyne | Market cap as of June 2026 (approx.) | All figures in ₹ Crore unless stated
A5: Company | B5: Revenue | C5: EBITDA | D5: EBITDA % | E5: PAT | F5: Mkt Cap | G5: Net Debt | H5: EV | I5: EV/EBITDA | J5: P/E
A6: Dixon Technologies | B6: 38860 | C6: 1943 | D6: 0.05 | E6: 1215 | F6: 75000 | G6: 200 | H6: 75200 | I6: 38.7 | J6: 61.7
A7: Amber Enterprises | B7: 5200 | C7: 442 | D7: 0.085 | E7: 148 | F7: 20000 | G7: 600 | H7: 20600 | I7: 46.6 | J7: 135
A8: Kaynes Technology | B8: 1800 | C8: 270 | D8: 0.15 | E8: 175 | F8: 14000 | G8: 150 | H8: 14150 | I8: 52.4 | J8: 80
A9: Syrma SGS Technology | B9: 2800 | C9: 196 | D9: 0.07 | E9: 100 | F9: 6500 | G9: 350 | H9: 6850 | I9: 34.9 | J9: 65
A11: Peer Median (ex-Dixon) | B11: =MEDIAN(B7:B9) | C11: =MEDIAN(C7:C9) | D11: =MEDIAN(D7:D9) | E11: =MEDIAN(E7:E9) | F11: =MEDIAN(F7:F9) | G11: =MEDIAN(G7:G9) | H11: =MEDIAN(H7:H9) | I11: =MEDIAN(I7:I9) | J11: =MEDIAN(J7:J9)
A12: Peer Mean (ex-Dixon) | B12: =AVERAGE(B7:B9) | C12: =AVERAGE(C7:C9) | D12: =AVERAGE(D7:D9) | E12: =AVERAGE(E7:E9) | F12: =AVERAGE(F7:F9) | G12: =AVERAGE(G7:G9) | H12: =AVERAGE(H7:H9) | I12: =AVERAGE(I7:I9) | J12: =AVERAGE(J7:J9)
A15: POSITIONING ANALYSIS
A16: ► Dixon's EBITDA margin (5.0%) is below EMS peers due to high mobile (low-margin) revenue mix — Kaynes (15%) is PCBA-focused (higher value-add)
A17: ► Dixon trades at 38.7x EV/EBITDA vs. peer median ~46-52x, suggesting relative value or market pricing in lower margin profile
A18: ► Kaynes & Amber have better margins but much smaller scale — Dixon is the only large-cap pure EMS play in India
A19: ► China+1, PLI scheme benefits, and new category wins (IT hardware, wearables) are key re-rating catalysts for Dixon
A20: ► Key risk: margin compression if mobile mix rises further; PLI scheme sunset risk post FY27
