Workbook

Sheet Cover
A1: DIXON TECHNOLOGIES (INDIA) LTD
A2: DCF Valuation Model — Step 1: Revenue Model
A4: Company | B4: Dixon Technologies (India) Limited
A5: NSE Ticker | B5: DIXON
A6: Sector | B6: Electronics Manufacturing Services (EMS)
A7: Model prepared by | B7: Om Chaudhari
A8: Date | B8: 46181
A9: Base year | B9: FY2026 (ended March 31, 2026)
A10: Projection period | B10: FY2027E – FY2031E
A11: Currency | B11: ₹ Indian Rupee (Crore)
A13: Data source | B13: Dixon Q4 FY26 Results (May 12, 2026)
A14: Annual report | B14: https://www.dixoninfo.com/financial-performance
A15: Screener.in | B15: screener.in/company/DIXON/consolidated/
A17: SHEET GUIDE
A18: Revenue Model | B18: Historical + projected revenue by segment with growth assumptions
A19: P&L Summary | B19: Projected income statement (EBITDA, PAT, margins)
A20: Assumptions | B20: All growth rates and margin inputs — change these to run scenarios
A22: COLOUR KEY
A23: BLUE text | B23: Hardcoded inputs — you can change these
A24: BLACK text | B24: Formulas — do not edit
A25: YELLOW fill | B25: Key assumptions that need your attention
A26: Light blue cols | B26: Historical actuals
A27: Light green cols | B27: Projections (your estimates)

Sheet Revenue Model
A1: DIXON TECHNOLOGIES — REVENUE MODEL (₹ Crore)
A2: All figures in ₹ Crore unless stated. Blue = inputs. Black = formulas.
A4: Segment | B4: FY2022 (Actual) | C4: FY2023 (Actual) | D4: FY2024 (Actual) | E4: FY2025 (Actual) | F4: FY2026 (Actual) | G4: FY2027 (Est.) | H4: FY2028 (Est.)
A6: Mobile & EMS | B6: 9212 | C6: 10450 | D6: 14342 | E6: 33049 | F6: 43986
A7: Consumer Electronics & Appliances | B7: 904 | C7: 901 | D7: 1850 | E7: 3491 | F7: 3421
A8: Home Appliances | B8: 420 | C8: 653 | D8: 1006 | E8: 1285 | F8: 1466
A9: Lighting Products | B9: 153 | C9: 188 | D9: 493 | E9: 1035 | F9: 0 | H9: FY26: Lighting revenue via Signify JV entity — not in Dixon standalone P&L
A10: Total Revenue from Operations | B10: =SUM(B6:B9) -> 10689 | C10: =SUM(C6:C9) -> 12192 | D10: =SUM(D6:D9) -> 17691 | E10: =SUM(E6:E9) -> 38860 | F10: =SUM(F6:F9) -> 48873
A12: YoY REVENUE GROWTH
A13: Mobile & EMS | B13: n/a | C13: =(C6-B6)/B6 -> 0.13438993 | D13: =(D6-C6)/C6 -> 0.37244019 | E13: =(E6-D6)/D6 -> 1.3043509 | F13: =(F6-E6)/E6 -> 0.33093286
A14: Consumer Electronics & Appliances | B14: n/a | C14: =(C7-B7)/B7 -> -0.0033185841 | D14: =(D7-C7)/C7 -> 1.0532741 | E14: =(E7-D7)/D7 -> 0.88702703 | F14: =(F7-E7)/E7 -> -0.020051561
A15: Home Appliances | B15: n/a | C15: =(C8-B8)/B8 -> 0.5547619 | D15: =(D8-C8)/C8 -> 0.54058193 | E15: =(E8-D8)/D8 -> 0.27733598 | F15: =(F8-E8)/E8 -> 0.14085603
A16: Lighting Products | B16: n/a | C16: =(C9-B9)/B9 -> 0.22875817 | D16: =(D9-C9)/C9 -> 1.6223404 | E16: =(E9-D9)/D9 -> 1.0993915 | F16: =(F9-E9)/E9 -> -1
A17: Total Revenue Growth | B17: n/a | C17: =(C10-B10)/B10 -> 0.14061184 | D17: =(D10-C10)/C10 -> 0.45103346 | E17: =(E10-D10)/D10 -> 1.1965971 | F17: =(F10-E10)/E10 -> 0.25766855
A19: PROJECTION ASSUMPTIONS (FY2027E – FY2028E) — CHANGE THESE
A20: Segment | G20: FY2027E | H20: FY2028E
A21: Mobile & EMS growth rate | G21: 0.2 | H21: 0.18 | I21: Base: 20%. Bull: 30% (Vivo approval). Bear: 10% (Samsung volume cut)
A22: Consumer Electronics & Appliances growth rate | G22: 0.08 | H22: 0.1 | I22: Flat to modest growth. Low visibility.
A23: Home Appliances growth rate | G23: 0.18 | H23: 0.2 | I23: New product launches (dishwashers, vacuum cleaners)
A24: Lighting Products growth rate | G24: 0.48 | H24: 0.25 | I24: Signify JV guided ~₹1,700 Cr FY27 from ₹850 Cr FY26 (~100%)
A26: PROJECTED REVENUE BY SEGMENT
A27: Mobile & EMS | G27: =F6*(1+G21) -> 52783.2 | H27: =G27*(1+H21) -> 62284.176
A28: Consumer Electronics & Appliances | G28: =F7*(1+G22) -> 3694.68 | H28: =G28*(1+H22) -> 4064.148
A29: Home Appliances | G29: =F8*(1+G23) -> 1729.88 | H29: =G29*(1+H23) -> 2075.856
A30: Lighting Products | G30: =F9*(1+G24) -> 0 | H30: =G30*(1+H24) -> 0
A31: Total Projected Revenue | G31: =SUM(G27:G30) -> 58207.76 | H31: =SUM(H27:H30) -> 68424.18
A32: Total Revenue Growth (projected) | G32: =(G31-F10)/F10 -> 0.19100035 | H32: =(H31-G31)/G31 -> 0.17551646

Sheet P&L Summary
A1: DIXON TECHNOLOGIES — P&L SUMMARY (₹ Crore)
A2: Historical actuals + projected income statement. Formulas link to Revenue Model sheet.
A4: P&L Line Item | B4: FY2022 (Actual) | C4: FY2023 (Actual) | D4: FY2024 (Actual) | E4: FY2025 (Actual) | F4: FY2026 (Actual) | G4: FY2027 (Est.) | H4: FY2028 (Est.)
A5: Revenue from Operations | B5: ='Revenue Model'!B10 -> 10689 | C5: ='Revenue Model'!C10 -> 12192 | D5: ='Revenue Model'!D10 -> 17691 | E5: ='Revenue Model'!E10 -> 38860 | F5: ='Revenue Model'!F10 -> 48873
A6: EBITDA | B6: 371 | C6: 513 | D6: 698 | E6: 1528 | F6: 2580
A7: EBITDA Margin (%) | B7: =B6/B5 -> 0.034708579 | C7: =C6/C5 -> 0.042076772 | D7: =D6/D5 -> 0.03945509 | E7: =E6/E5 -> 0.039320638 | F7: =F6/F5 -> 0.052789884
A8: Depreciation & Amortisation | B8: 68 | C8: 95 | D8: 131 | E8: 281 | F8: 393
A9: EBIT | B9: =B6-B8 -> 303 | C9: =C6-C8 -> 418 | D9: =D6-D8 -> 567 | E9: =E6-E8 -> 1247 | F9: =F6-F8 -> 2187
A10: Interest / Finance Costs | B10: 34 | C10: 38 | D10: 53 | E10: 154 | F10: 137
A11: PBT (pre-exceptional) | B11: =B9-B10 -> 269 | C11: =C9-C10 -> 380 | D11: =D9-D10 -> 514 | E11: =E9-E10 -> 1093 | F11: =F9-F10 -> 2050
A12: Tax | B12: 71 | C12: 99 | D12: 137 | E12: 280 | F12: 527
A13: PAT (reported) | B13: 182 | C13: 255 | D13: 368 | E13: 1233 | F13: 1644
A14: PAT Margin (%) | B14: =B13/B5 -> 0.01702685 | C14: =C13/C5 -> 0.020915354 | D14: =D13/D5 -> 0.020801538 | E14: =E13/E5 -> 0.031729285 | F14: =F13/F5 -> 0.033638205
A15: EPS (Diluted, ₹) | B15: 31 | C15: 42.9 | D15: 61.7 | E15: 202.6 | F15: 269.4
A18: MARGIN ASSUMPTIONS — CHANGE THESE
A19: Assumption | G19: FY2027E | H19: FY2028E
A20: EBITDA Margin assumption | G20: 0.055 | H20: 0.06 | I20: FY26 actual was 5.3%. Mgmt guides improvement via backward integration (QTech camera modules). Use 5.5–6.0% for base case.
A21: D&A as % of Revenue | G21: 0.009 | H21: 0.01 | I21: Dixon is capex-heavy (₹1,200 Cr FY26 capex). D&A rising ~40% YoY. Estimate ~0.9–1.0% of revenue.
A22: Finance Costs (₹ Cr, fixed est) | G22: 150 | H22: 160 | I22: Negative NWC means low working capital funding needs. Use ~₹150 Cr fixed estimate.
A23: Effective Tax Rate | G23: 0.26 | H23: 0.26 | I23: Company pays ~26% effective tax. Relatively stable.
A26: PROJECTED P&L
A27: Revenue from Operations | G27: ='Revenue Model'!G31 -> 58207.76 | H27: ='Revenue Model'!H31 -> 68424.18
A28: EBITDA | G28: =G27*G20 -> 3201.4268 | H28: =H27*H20 -> 4105.4508
A29: EBITDA Margin (%) | G29: =G28/G27 -> 0.055 | H29: =H28/H27 -> 0.06
A30: Depreciation & Amortisation | G30: =G27*G21 -> 523.86984 | H30: =H27*H21 -> 684.2418
A31: EBIT | G31: =G28-G30 -> 2677.557 | H31: =H28-H30 -> 3421.209
A32: Finance Costs | G32: =G22 -> 150 | H32: =H22 -> 160
A33: PBT | G33: =G31-G32 -> 2527.557 | H33: =H31-H32 -> 3261.209
A34: Tax | G34: =G33*G23 -> 657.16481 | H34: =H33*H23 -> 847.91434
A35: PAT (projected) | G35: =G33-G34 -> 1870.3922 | H35: =H33-H34 -> 2413.2947
A36: PAT Margin (%) | G36: =G35/G27 -> 0.032133038 | H36: =H35/H27 -> 0.035269618

Sheet Assumptions
A1: KEY ASSUMPTIONS & SOURCES — DIXON TECHNOLOGIES
A2: Assumption | B2: Value | C2: Rationale / Source
A3: REVENUE GROWTH (Base Case)
A4: Mobile & EMS — FY27E | B4: ='Revenue Model'!G21 -> 0.2 | C4: Mgmt guided 60–65 mn phones FY28; telecom ₹7,500 Cr FY27 vs ₹5,000 Cr FY26. Flat domestic mobile, offset by higher realizations (+12-15%).
A5: Mobile & EMS — FY28E | B5: ='Revenue Model'!H21 -> 0.18 | C5: Camera module scale-up (₹2,500 Cr vs ₹1,700 Cr). Backward integration margin uplift. Conservative post Vivo uncertainty.
A6: Consumer Electronics — FY27E | B6: ='Revenue Model'!G22 -> 0.08 | C6: Soft demand for LED TVs. Modest growth from new clients.
A7: Consumer Electronics — FY28E | B7: ='Revenue Model'!H22 -> 0.1 | C7: Monitor and IFPD segment ramp expected.
A8: Home Appliances — FY27E | B8: ='Revenue Model'!G23 -> 0.18 | C8: New categories launching: robotic vacuum, dishwasher, microwave. Capacity expansion.
A9: Home Appliances — FY28E | B9: ='Revenue Model'!H23 -> 0.2 | C9: Full year contribution from new categories.
A10: Lighting Products — FY27E | B10: ='Revenue Model'!G24 -> 0.48 | C10: Signify JV guided ~₹1,700 Cr vs ~₹850 Cr FY26 actuals (~2x).
A11: Lighting Products — FY28E | B11: ='Revenue Model'!H24 -> 0.25 | C11: JV matures, growth moderates. Export potential materializing.
A13: MARGIN ASSUMPTIONS
A14: EBITDA Margin — FY27E | B14: ='P&L Summary'!G20 -> 0.055 | C14: FY26 was 5.3%. Backward integration benefit begins. Mobile margin 2.8–3.2% near term (mgmt guided).
A15: EBITDA Margin — FY28E | B15: ='P&L Summary'!H20 -> 0.06 | C15: Camera module in-house ramps, improving blended margin.
A16: D&A % Revenue — FY27E | B16: ='P&L Summary'!G21 -> 0.009 | C16: Capex ₹1,200 Cr in FY26. D&A rising ~40% YoY. Estimate ~0.9% of revenue.
A17: Tax Rate | B17: ='P&L Summary'!G23 -> 0.26 | C17: Effective rate stable at ~26% historically.
A19: KEY RISKS TO MODEL
A20: BEAR CASE TRIGGER | B20: Samsung volume -20% | C20: Mobile & EMS grows only 5% YoY. Revenue misses ₹57,000 Cr.
A21: BULL CASE TRIGGER | B21: Vivo approval | C21: Adds 20–22 mn units. Mobile & EMS grows 35%+ YoY.
A22: PLI RISK | B22: ₹1,110 Cr pending | C22: PLI incentive disbursement not confirmed. If delayed, PAT misses.
A24: SOURCES
A25: Annual filings | B25: BSE/NSE filing | C25: investor.dixon.in — Q4 FY26 results announced May 12, 2026
A26: Screener.in | B26: Free | C26: screener.in/company/DIXON/consolidated/
A27: Earnings call | B27: Quartr / BSE | C27: quartr.com/companies/dixon-technologies-india-limited_19412
A28: Analyst report | B28: ICICI Direct | C28: icicidirect.com — target ₹20,000 (Oct 2025 report)

Sheet WACC
A1: DIXON TECHNOLOGIES — WACC CALCULATION (₹ Crore)
A2: Source: BSE Q4 FY26 filing (May 12 2026) · TradingView beta · RBI / Trading Economics G-Sec
A4: A. COST OF EQUITY (CAPM: Re = Rf + β × ERP)
A5: Risk-Free Rate (Rf) | B5: 0.067 | D5: India 10-Year G-Sec yield. Source: Trading Economics / RBI, June 2026. Currently ~6.7% after yield spike on oil/Iran fears.
A6: Beta (β) | B6: 0.86 | D6: Source: TradingView NSE:DIXON. 1-year beta vs Nifty 50 = 0.86. Dixon less volatile than market — large-cap EMS with sticky clients.
A7: Equity Risk Premium (ERP) | B7: 0.075 | D7: India ERP per Damodaran (Jan 2026) = ~7.5%. Reflects emerging market risk over G-Sec. Standard for Indian equity valuation.
A8: Cost of Equity (Re) | B8: =B5+B6*B7 -> 0.1315 | D8: CAPM: Rf + β × ERP = 6.7% + 0.86 × 7.5% = 13.15%. Higher than US (~9%) due to India risk premium.
A10: B. COST OF DEBT (Post-Tax)
A11: Pre-Tax Cost of Debt (Rd) | B11: 0.08 | D11: Proxy: ICRA AA-rated corporate bond spread ~130bps over G-Sec. 6.7% + 1.3% = 8.0%. Dixon has ICRA AA Stable rating.
A12: Effective Tax Rate | B12: 0.26 | D12: FY26 actual effective tax rate = 26%. Consistent over 3 years. Source: BSE P&L filing.
A13: Post-Tax Cost of Debt (Rd × (1-t)) | B13: =B11*(1-B12) -> 0.0592
A15: C. CAPITAL STRUCTURE (Market Value Weights)
A16: Market Capitalisation (₹ Cr) | B16: 68549 | D16: Current market cap ~₹68,549 Cr at ₹11,848/share × 5.79 Cr shares. Source: NSE / TradingView, May 2026.
A17: Total Borrowings — FY26 (₹ Cr) | B17: 467 | D17: Total borrowings ₹467 Cr (short-term working capital). Source: BSE Q4 FY26 balance sheet. Zero long-term debt.
A18: Cash & Equivalents (₹ Cr) | B18: 767 | D18: Closing cash ₹767 Cr FY26 vs ₹231 Cr FY25 — tripled. Source: BSE Q4 FY26 cash flow statement.
A19: Net Debt (Debt − Cash) | B19: =B17-B18 -> -300 | D19: Negative = Net Cash position. Dixon has ₹300 Cr net cash — fortress balance sheet for a ₹68,000 Cr mkt cap company.
A20: Total Firm Value (E + D) | B20: =B16+B17 -> 69016
A21: Weight of Equity (E/V) | B21: =B16/B20 -> 0.99323345 | D21: 99.3% equity — nearly all-equity company.
A22: Weight of Debt (D/V) | B22: =B17/B20 -> 0.0067665469 | D22: Only 0.7% debt weight — WACC ≈ Re.
A24: D. WACC = Re × (E/V) + Rd(1-t) × (D/V)
A25: WACC | B25: =B8*B21+B13*B22 -> 0.13101078 | D25: WACC approx 13.1%. Near all-equity so WACC approximates cost of equity. Use 13.0-13.5% in sensitivity.
A27: E. SHARES & PRICE DATA (for Equity Bridge)
A28: Diluted Shares Outstanding (Cr) | B28: 6.1 | D28: FY26 PAT ₹1,644 Cr ÷ diluted EPS ₹269.4 = 6.10 Cr shares. Source: BSE Q4 FY26 filing.
A29: Current Stock Price (₹) | B29: 11848 | D29: NSE closing price. Source: TradingView NSE:DIXON, June 2026. Use for comparison with DCF implied price.
A30: Shares × Price = Market Cap check | B30: =B28*B29 -> 72272.8 | D30: Should ≈ B16 market cap. Small difference due to rounding in share count.

Sheet DCF Valuation
A1: DIXON TECHNOLOGIES — DCF VALUATION (₹ Crore)
A2: 5-year explicit projection (FY27E–FY31E) + Terminal Value. Blue = inputs. Black = formulas. Green = cross-sheet.
A4: Line Item | B4: FY2026 (Base) | C4: FY2027E | D4: FY2028E | E4: FY2029E | F4: FY2030E | G4: FY2031E
A5: DCF ASSUMPTIONS (change yellow cells)
A6: Revenue Growth Rate | C6: ='Revenue Model'!G32 -> 0.19100035 | D6: ='Revenue Model'!H32 -> 0.17551646 | E6: 0.15 | F6: 0.13 | G6: 0.1 | H6: Links to Revenue Model for FY27-28. FY29-31 assume deceleration toward terminal growth.
A7: EBITDA Margin | B7: 0.053 | C7: 0.055 | D7: 0.06 | E7: 0.065 | F7: 0.07 | G7: 0.075 | H7: Base = FY26 actual 5.3%. Expands 20-30bps/yr via backward integration (camera modules, components).
A8: D&A as % of Revenue | B8: 0.008 | C8: 0.009 | D8: 0.01 | E8: 0.01 | F8: 0.01 | G8: 0.01 | H8: Rising with capex. FY26 actual 0.80%. Reaches ~1.0% by FY29 as capex ₹1,200 Cr depreciates.
A9: Capex as % of Revenue | B9: 0.025 | C9: 0.025 | D9: 0.023 | E9: 0.02 | F9: 0.018 | G9: 0.015 | H9: FY26 actual 2.46% (₹1,200 Cr/₹48,873 Cr). Declines as initial capacity build completes.
A10: NWC Days (negative = supplier funded) | B10: -7 | C10: -7 | D10: -7 | E10: -7 | F10: -7 | G10: -7 | H10: Dixon has negative NWC: clients pay before suppliers are paid. -7 days = structural cash benefit.
A12: FREE CASH FLOW TO FIRM (FCFF) BUILD
A13: Revenue from Operations | B13: ='P&L Summary'!F5 -> 48873 | C13: =B13*(1+C6) -> 58207.76 | D13: =C13*(1+D6) -> 68424.18 | E13: =D13*(1+E6) -> 78687.807 | F13: =E13*(1+F6) -> 88917.222 | G13: =F13*(1+G6) -> 97808.944
A14: EBITDA | B14: =B13*B7 -> 2590.269 | C14: =C13*C7 -> 3201.4268 | D14: =D13*D7 -> 4105.4508 | E14: =E13*E7 -> 5114.7075 | F14: =F13*F7 -> 6224.2055 | G14: =G13*G7 -> 7335.6708
A15: Less: Depreciation & Amortisation (D&A) | B15: =B13*B8 -> 390.984 | C15: =C13*C8 -> 523.86984 | D15: =D13*D8 -> 684.2418 | E15: =E13*E8 -> 786.87807 | F15: =F13*F8 -> 889.17222 | G15: =G13*G8 -> 978.08944
A16: EBIT (Operating Profit) | B16: =B14-B15 -> 2199.285 | C16: =C14-C15 -> 2677.557 | D16: =D14-D15 -> 3421.209 | E16: =E14-E15 -> 4327.8294 | F16: =F14-F15 -> 5335.0333 | G16: =G14-G15 -> 6357.5814
A17: Less: Tax on EBIT (@ 26%) | B17: =B16*WACC!B12 -> 571.8141 | C17: =C16*WACC!B12 -> 696.16481 | D17: =D16*WACC!B12 -> 889.51434 | E17: =E16*WACC!B12 -> 1125.2356 | F17: =F16*WACC!B12 -> 1387.1087 | G17: =G16*WACC!B12 -> 1652.9712
A18: NOPAT (Net Operating PAT = EBIT × (1-t)) | B18: =B16-B17 -> 1627.4709 | C18: =C16-C17 -> 1981.3922 | D18: =D16-D17 -> 2531.6947 | E18: =E16-E17 -> 3202.5937 | F18: =F16-F17 -> 3947.9247 | G18: =G16-G17 -> 4704.6102
A19: Add back: D&A (non-cash) | B19: =B15 -> 390.984 | C19: =C15 -> 523.86984 | D19: =D15 -> 684.2418 | E19: =E15 -> 786.87807 | F19: =F15 -> 889.17222 | G19: =G15 -> 978.08944
A20: Less: Capital Expenditure (Capex) | B20: =B13*B9 -> 1221.825 | C20: =C13*C9 -> 1455.194 | D20: =D13*D9 -> 1573.7561 | E20: =E13*E9 -> 1573.7561 | F20: =F13*F9 -> 1600.51 | G20: =G13*G9 -> 1467.1342
A21: Less: Change in Working Capital (ΔNWC) | B21: =0 -> 0 | C21: =(C13-B13)*C10/365 -> -179.02279 | D21: =(D13-C13)*D10/365 -> -195.93134 | E21: =(E13-D13)*E10/365 -> -196.83668 | F21: =(F13-E13)*F10/365 -> -196.18056 | G21: =(G13-F13)*G10/365 -> -170.52618
A22: FREE CASH FLOW TO FIRM (FCFF) | B22: =B18+B19-B20-B21 -> 796.6299 | C22: =C18+C19-C20-C21 -> 1229.0908 | D22: =D18+D19-D20-D21 -> 1838.1117 | E22: =E18+E19-E20-E21 -> 2612.5524 | F22: =F18+F19-F20-F21 -> 3432.7674 | G22: =G18+G19-G20-G21 -> 4386.0917
A24: DISCOUNTING (WACC from WACC sheet)
A25: Discount Period (mid-year convention) | B25: 0 | C25: 0.5 | D25: 1.5 | E25: 2.5 | F25: 3.5 | G25: 4.5
A26: Discount Factor = 1 / (1+WACC)^t | B26: =1 -> 1 | C26: =1/(1+WACC!B25)^C25 -> 0.94030042 | D26: =1/(1+WACC!B25)^D25 -> 0.8313806 | E26: =1/(1+WACC!B25)^E25 -> 0.73507752 | F26: =1/(1+WACC!B25)^F25 -> 0.64992972 | G26: =1/(1+WACC!B25)^G25 -> 0.57464503
A27: PV of FCFF = FCFF × Discount Factor | B27: =0 -> 0 | C27: =C22*C26 -> 1155.7146 | D27: =D22*D26 -> 1528.1704 | E27: =E22*E26 -> 1920.4285 | F27: =F22*F26 -> 2231.0576 | G27: =G22*G26 -> 2520.4458
A29: TERMINAL VALUE (Gordon Growth Model)
A30: Terminal Growth Rate (g) | B30: 0.065 | H30: 6.5% = India nominal GDP growth (~7% nominal GDP growth). Conservative for a company management targets ₹1L Cr revenue.
A31: Terminal Year FCFF (FY31E) | B31: =G22 -> 4386.0917 | H31: Last projection year FCFF (FY31E). Links from FCFF row above.
A32: Terminal Value (TV) | B32: =G22*(1+B30)/(WACC!B25-B30) -> 70764.013 | H32: Gordon Growth: TV = FCFF × (1+g) / (WACC−g). Sensitive to g assumption — run sensitivity.
A33: PV of Terminal Value | B33: =B32*G26 -> 40664.188 | H33: Discount TV back to today using FY31E discount factor.
A35: ENTERPRISE VALUE → EQUITY VALUE → PRICE PER SHARE
A36: Sum of PV of FCFFs | B36: =SUM(C27:G27) -> 9355.8168 | H36: Sum of discounted FCFFs for FY27E–FY31E explicit period.
A37: PV of Terminal Value | B37: =B33 -> 40664.188 | H37: Links from TV section above.
A38: Enterprise Value (EV) | B38: =B36+B37 -> 50020.005 | H38: Total EV = PV explicit FCFFs + PV Terminal Value.
A39: TV as % of EV | B39: =B37/B38 -> 0.8129585 | H39: Should typically be 60-80% for high-growth companies. >90% means model is terminal-value dependent.
A40: Add: Cash (₹ Cr) | B40: =WACC!B18 -> 767 | H40: Cash ₹767 Cr from balance sheet. Links to WACC sheet.
A41: Less: Total Debt (₹ Cr) | B41: =WACC!B17 -> 467 | H41: Total borrowings ₹467 Cr. Links to WACC sheet.
A42: Equity Value (₹ Cr) | B42: =B38+B40-B41 -> 50320.005 | H42: EV + Cash - Debt = Equity Value available to shareholders.
A43: Diluted Shares (Cr) | B43: =WACC!B28 -> 6.1 | H43: 6.10 Cr diluted shares. Links to WACC sheet.
A44: DCF Price per Share (₹) | B44: =B42/B43 -> 8249.1812 | H44: Equity Value ÷ Shares. Multiply by 100 because shares stated in Cr and value in Cr.
A45: Current Market Price (₹) | B45: =WACC!B29 -> 11848 | H45: Links to WACC sheet. Compare with DCF implied price.
...

Sheet Sensitivity
A1: DIXON TECHNOLOGIES — SENSITIVITY ANALYSIS
A2: Shows DCF price per share across WACC and Terminal Growth Rate combinations.
A4: TABLE 1: DCF Price per Share (₹) | WACC (rows) vs Terminal Growth Rate (cols)
A5: WACC \ g → | B5: 0.055 | C5: 0.06 | D5: 0.065 | E5: 0.07 | F5: 0.075
A6: 0.115 | B6: =(('DCF Valuation'!C22/(1+A6)^0.5+'DCF Valuation'!D22/(1+A6)^1.5+'DCF Valuation'!E22/(1+A6)^2.5+'DCF Valuation'!F22/(1+A6)^3.5+'DCF Valuation'!G22/(1+A6)^4.5)+('DCF Valuation'!G22*(1+B5)/(A6-B5))/(1+A6)^4.5+WACC!B18-WACC!B17)/WACC!B28 -> 9393.8261 | C6: =(('DCF Valuation'!C22/(1+A6)^0.5+'DCF Valuation'!D22/(1+A6)^1.5+'DCF Valuation'!E22/(1+A6)^2.5+'DCF Valuation'!F22/(1+A6)^3.5+'DCF Valuation'!G22/(1+A6)^4.5)+('DCF Valuation'!G22*(1+C5)/(A6-C5))/(1+A6)^4.5+WACC!B18-WACC!B17)/WACC!B28 -> 10138.116 | D6: =(('DCF Valuation'!C22/(1+A6)^0.5+'DCF Valuation'!D22/(1+A6)^1.5+'DCF Valuation'!E22/(1+A6)^2.5+'DCF Valuation'!F22/(1+A6)^3.5+'DCF Valuation'!G22/(1+A6)^4.5)+('DCF Valuation'!G22*(1+D5)/(A6-D5))/(1+A6)^4.5+WACC!B18-WACC!B17)/WACC!B28 -> 11031.263 | E6: =(('DCF Valuation'!C22/(1+A6)^0.5+'DCF Valuation'!D22/(1+A6)^1.5+'DCF Valuation'!E22/(1+A6)^2.5+'DCF Valuation'!F22/(1+A6)^3.5+'DCF Valuation'!G22/(1+A6)^4.5)+('DCF Valuation'!G22*(1+E5)/(A6-E5))/(1+A6)^4.5+WACC!B18-WACC!B17)/WACC!B28 -> 12122.888 | F6: =(('DCF Valuation'!C22/(1+A6)^0.5+'DCF Valuation'!D22/(1+A6)^1.5+'DCF Valuation'!E22/(1+A6)^2.5+'DCF Valuation'!F22/(1+A6)^3.5+'DCF Valuation'!G22/(1+A6)^4.5)+('DCF Valuation'!G22*(1+F5)/(A6-F5))/(1+A6)^4.5+WACC!B18-WACC!B17)/WACC!B28 -> 13487.418
A7: 0.12 | B7: =(('DCF Valuation'!C22/(1+A7)^0.5+'DCF Valuation'!D22/(1+A7)^1.5+'DCF Valuation'!E22/(1+A7)^2.5+'DCF Valuation'!F22/(1+A7)^3.5+'DCF Valuation'!G22/(1+A7)^4.5)+('DCF Valuation'!G22*(1+B5)/(A7-B5))/(1+A7)^4.5+WACC!B18-WACC!B17)/WACC!B28 -> 8634.8747 | C7: =(('DCF Valuation'!C22/(1+A7)^0.5+'DCF Valuation'!D22/(1+A7)^1.5+'DCF Valuation'!E22/(1+A7)^2.5+'DCF Valuation'!F22/(1+A7)^3.5+'DCF Valuation'!G22/(1+A7)^4.5)+('DCF Valuation'!G22*(1+C5)/(A7-C5))/(1+A7)^4.5+WACC!B18-WACC!B17)/WACC!B28 -> 9254.8725 | D7: =(('DCF Valuation'!C22/(1+A7)^0.5+'DCF Valuation'!D22/(1+A7)^1.5+'DCF Valuation'!E22/(1+A7)^2.5+'DCF Valuation'!F22/(1+A7)^3.5+'DCF Valuation'!G22/(1+A7)^4.5)+('DCF Valuation'!G22*(1+D5)/(A7-D5))/(1+A7)^4.5+WACC!B18-WACC!B17)/WACC!B28 -> 9987.5973 | E7: =(('DCF Valuation'!C22/(1+A7)^0.5+'DCF Valuation'!D22/(1+A7)^1.5+'DCF Valuation'!E22/(1+A7)^2.5+'DCF Valuation'!F22/(1+A7)^3.5+'DCF Valuation'!G22/(1+A7)^4.5)+('DCF Valuation'!G22*(1+E5)/(A7-E5))/(1+A7)^4.5+WACC!B18-WACC!B17)/WACC!B28 -> 10866.867 | F7: =(('DCF Valuation'!C22/(1+A7)^0.5+'DCF Valuation'!D22/(1+A7)^1.5+'DCF Valuation'!E22/(1+A7)^2.5+'DCF Valuation'!F22/(1+A7)^3.5+'DCF Valuation'!G22/(1+A7)^4.5)+('DCF Valuation'!G22*(1+F5)/(A7-F5))/(1+A7)^4.5+WACC!B18-WACC!B17)/WACC!B28 -> 11941.53
A8: 0.125 | B8: =(('DCF Valuation'!C22/(1+A8)^0.5+'DCF Valuation'!D22/(1+A8)^1.5+'DCF Valuation'!E22/(1+A8)^2.5+'DCF Valuation'!F22/(1+A8)^3.5+'DCF Valuation'!G22/(1+A8)^4.5)+('DCF Valuation'!G22*(1+B5)/(A8-B5))/(1+A8)^4.5+WACC!B18-WACC!B17)/WACC!B28 -> 7985.0332 | C8: =(('DCF Valuation'!C22/(1+A8)^0.5+'DCF Valuation'!D22/(1+A8)^1.5+'DCF Valuation'!E22/(1+A8)^2.5+'DCF Valuation'!F22/(1+A8)^3.5+'DCF Valuation'!G22/(1+A8)^4.5)+('DCF Valuation'!G22*(1+C5)/(A8-C5))/(1+A8)^4.5+WACC!B18-WACC!B17)/WACC!B28 -> 8508.2391 | D8: =(('DCF Valuation'!C22/(1+A8)^0.5+'DCF Valuation'!D22/(1+A8)^1.5+'DCF Valuation'!E22/(1+A8)^2.5+'DCF Valuation'!F22/(1+A8)^3.5+'DCF Valuation'!G22/(1+A8)^4.5)+('DCF Valuation'!G22*(1+D5)/(A8-D5))/(1+A8)^4.5+WACC!B18-WACC!B17)/WACC!B28 -> 9118.646 | E8: =(('DCF Valuation'!C22/(1+A8)^0.5+'DCF Valuation'!D22/(1+A8)^1.5+'DCF Valuation'!E22/(1+A8)^2.5+'DCF Valuation'!F22/(1+A8)^3.5+'DCF Valuation'!G22/(1+A8)^4.5)+('DCF Valuation'!G22*(1+E5)/(A8-E5))/(1+A8)^4.5+WACC!B18-WACC!B17)/WACC!B28 -> 9840.036 | F8: =(('DCF Valuation'!C22/(1+A8)^0.5+'DCF Valuation'!D22/(1+A8)^1.5+'DCF Valuation'!E22/(1+A8)^2.5+'DCF Valuation'!F22/(1+A8)^3.5+'DCF Valuation'!G22/(1+A8)^4.5)+('DCF Valuation'!G22*(1+F5)/(A8-F5))/(1+A8)^4.5+WACC!B18-WACC!B17)/WACC!B28 -> 10705.704
A9: 0.131 | B9: =(('DCF Valuation'!C22/(1+A9)^0.5+'DCF Valuation'!D22/(1+A9)^1.5+'DCF Valuation'!E22/(1+A9)^2.5+'DCF Valuation'!F22/(1+A9)^3.5+'DCF Valuation'!G22/(1+A9)^4.5)+('DCF Valuation'!G22*(1+B5)/(A9-B5))/(1+A9)^4.5+WACC!B18-WACC!B17)/WACC!B28 -> 7318.9082 | C9: =(('DCF Valuation'!C22/(1+A9)^0.5+'DCF Valuation'!D22/(1+A9)^1.5+'DCF Valuation'!E22/(1+A9)^2.5+'DCF Valuation'!F22/(1+A9)^3.5+'DCF Valuation'!G22/(1+A9)^4.5)+('DCF Valuation'!G22*(1+C5)/(A9-C5))/(1+A9)^4.5+WACC!B18-WACC!B17)/WACC!B28 -> 7751.947 | D9: =(('DCF Valuation'!C22/(1+A9)^0.5+'DCF Valuation'!D22/(1+A9)^1.5+'DCF Valuation'!E22/(1+A9)^2.5+'DCF Valuation'!F22/(1+A9)^3.5+'DCF Valuation'!G22/(1+A9)^4.5)+('DCF Valuation'!G22*(1+D5)/(A9-D5))/(1+A9)^4.5+WACC!B18-WACC!B17)/WACC!B28 -> 8250.5977 | E9: =(('DCF Valuation'!C22/(1+A9)^0.5+'DCF Valuation'!D22/(1+A9)^1.5+'DCF Valuation'!E22/(1+A9)^2.5+'DCF Valuation'!F22/(1+A9)^3.5+'DCF Valuation'!G22/(1+A9)^4.5)+('DCF Valuation'!G22*(1+E5)/(A9-E5))/(1+A9)^4.5+WACC!B18-WACC!B17)/WACC!B28 -> 8830.9945 | F9: =(('DCF Valuation'!C22/(1+A9)^0.5+'DCF Valuation'!D22/(1+A9)^1.5+'DCF Valuation'!E22/(1+A9)^2.5+'DCF Valuation'!F22/(1+A9)^3.5+'DCF Valuation'!G22/(1+A9)^4.5)+('DCF Valuation'!G22*(1+F5)/(A9-F5))/(1+A9)^4.5+WACC!B18-WACC!B17)/WACC!B28 -> 9515.0335
A10: 0.135 | B10: =(('DCF Valuation'!C22/(1+A10)^0.5+'DCF Valuation'!D22/(1+A10)^1.5+'DCF Valuation'!E22/(1+A10)^2.5+'DCF Valuation'!F22/(1+A10)^3.5+'DCF Valuation'!G22/(1+A10)^4.5)+('DCF Valuation'!G22*(1+B5)/(A10-B5))/(1+A10)^4.5+WACC!B18-WACC!B17)/WACC!B28 -> 6930.7958 | C10: =(('DCF Valuation'!C22/(1+A10)^0.5+'DCF Valuation'!D22/(1+A10)^1.5+'DCF Valuation'!E22/(1+A10)^2.5+'DCF Valuation'!F22/(1+A10)^3.5+'DCF Valuation'!G22/(1+A10)^4.5)+('DCF Valuation'!G22*(1+C5)/(A10-C5))/(1+A10)^4.5+WACC!B18-WACC!B17)/WACC!B28 -> 7315.4594 | D10: =(('DCF Valuation'!C22/(1+A10)^0.5+'DCF Valuation'!D22/(1+A10)^1.5+'DCF Valuation'!E22/(1+A10)^2.5+'DCF Valuation'!F22/(1+A10)^3.5+'DCF Valuation'!G22/(1+A10)^4.5)+('DCF Valuation'!G22*(1+D5)/(A10-D5))/(1+A10)^4.5+WACC!B18-WACC!B17)/WACC!B28 -> 7755.0749 | E10: =(('DCF Valuation'!C22/(1+A10)^0.5+'DCF Valuation'!D22/(1+A10)^1.5+'DCF Valuation'!E22/(1+A10)^2.5+'DCF Valuation'!F22/(1+A10)^3.5+'DCF Valuation'!G22/(1+A10)^4.5)+('DCF Valuation'!G22*(1+E5)/(A10-E5))/(1+A10)^4.5+WACC!B18-WACC!B17)/WACC!B28 -> 8262.3237 | F10: =(('DCF Valuation'!C22/(1+A10)^0.5+'DCF Valuation'!D22/(1+A10)^1.5+'DCF Valuation'!E22/(1+A10)^2.5+'DCF Valuation'!F22/(1+A10)^3.5+'DCF Valuation'!G22/(1+A10)^4.5)+('DCF Valuation'!G22*(1+F5)/(A10-F5))/(1+A10)^4.5+WACC!B18-WACC!B17)/WACC!B28 -> 8854.1138
A11: 0.14 | B11: =(('DCF Valuation'!C22/(1+A11)^0.5+'DCF Valuation'!D22/(1+A11)^1.5+'DCF Valuation'!E22/(1+A11)^2.5+'DCF Valuation'!F22/(1+A11)^3.5+'DCF Valuation'!G22/(1+A11)^4.5)+('DCF Valuation'!G22*(1+B5)/(A11-B5))/(1+A11)^4.5+WACC!B18-WACC!B17)/WACC!B28 -> 6497.5003 | C11: =(('DCF Valuation'!C22/(1+A11)^0.5+'DCF Valuation'!D22/(1+A11)^1.5+'DCF Valuation'!E22/(1+A11)^2.5+'DCF Valuation'!F22/(1+A11)^3.5+'DCF Valuation'!G22/(1+A11)^4.5)+('DCF Valuation'!G22*(1+C5)/(A11-C5))/(1+A11)^4.5+WACC!B18-WACC!B17)/WACC!B28 -> 6831.7276 | D11: =(('DCF Valuation'!C22/(1+A11)^0.5+'DCF Valuation'!D22/(1+A11)^1.5+'DCF Valuation'!E22/(1+A11)^2.5+'DCF Valuation'!F22/(1+A11)^3.5+'DCF Valuation'!G22/(1+A11)^4.5)+('DCF Valuation'!G22*(1+D5)/(A11-D5))/(1+A11)^4.5+WACC!B18-WACC!B17)/WACC!B28 -> 7210.5186 | E11: =(('DCF Valuation'!C22/(1+A11)^0.5+'DCF Valuation'!D22/(1+A11)^1.5+'DCF Valuation'!E22/(1+A11)^2.5+'DCF Valuation'!F22/(1+A11)^3.5+'DCF Valuation'!G22/(1+A11)^4.5)+('DCF Valuation'!G22*(1+E5)/(A11-E5))/(1+A11)^4.5+WACC!B18-WACC!B17)/WACC!B28 -> 7643.4226 | F11: =(('DCF Valuation'!C22/(1+A11)^0.5+'DCF Valuation'!D22/(1+A11)^1.5+'DCF Valuation'!E22/(1+A11)^2.5+'DCF Valuation'!F22/(1+A11)^3.5+'DCF Valuation'!G22/(1+A11)^4.5)+('DCF Valuation'!G22*(1+F5)/(A11-F5))/(1+A11)^4.5+WACC!B18-WACC!B17)/WACC!B28 -> 8142.9272
A13: ↑ Yellow cell = base case (WACC 13.1%, g 6.5%)
A14: Current market price for reference: | C14: =WACC!B29 -> 11848 | D14: ← If DCF price > this, stock looks undervalued on your assumptions
A16: TABLE 2: Impact on EBITDA (₹ Cr) | Revenue Growth (rows) vs EBITDA Margin (cols)
A17: Revenue Growth (FY27E) \ Margin → | B17: 0.05 | C17: 0.055 | D17: 0.06 | E17: 0.065 | F17: 0.07
A18: 0.1 | B18: ='P&L Summary'!F5*(1+A18)*B17 -> 2688.015 | C18: ='P&L Summary'!F5*(1+A18)*C17 -> 2956.8165 | D18: ='P&L Summary'!F5*(1+A18)*D17 -> 3225.618 | E18: ='P&L Summary'!F5*(1+A18)*E17 -> 3494.4195 | F18: ='P&L Summary'!F5*(1+A18)*F17 -> 3763.221
A19: 0.15 | B19: ='P&L Summary'!F5*(1+A19)*B17 -> 2810.1975 | C19: ='P&L Summary'!F5*(1+A19)*C17 -> 3091.2172 | D19: ='P&L Summary'!F5*(1+A19)*D17 -> 3372.237 | E19: ='P&L Summary'!F5*(1+A19)*E17 -> 3653.2568 | F19: ='P&L Summary'!F5*(1+A19)*F17 -> 3934.2765
A20: 0.18 | B20: ='P&L Summary'!F5*(1+A20)*B17 -> 2883.507 | C20: ='P&L Summary'!F5*(1+A20)*C17 -> 3171.8577 | D20: ='P&L Summary'!F5*(1+A20)*D17 -> 3460.2084 | E20: ='P&L Summary'!F5*(1+A20)*E17 -> 3748.5591 | F20: ='P&L Summary'!F5*(1+A20)*F17 -> 4036.9098
A21: 0.2 | B21: ='P&L Summary'!F5*(1+A21)*B17 -> 2932.38 | C21: ='P&L Summary'!F5*(1+A21)*C17 -> 3225.618 | D21: ='P&L Summary'!F5*(1+A21)*D17 -> 3518.856 | E21: ='P&L Summary'!F5*(1+A21)*E17 -> 3812.094 | F21: ='P&L Summary'!F5*(1+A21)*F17 -> 4105.332
A22: 0.25 | B22: ='P&L Summary'!F5*(1+A22)*B17 -> 3054.5625 | C22: ='P&L Summary'!F5*(1+A22)*C17 -> 3360.0188 | D22: ='P&L Summary'!F5*(1+A22)*D17 -> 3665.475 | E22: ='P&L Summary'!F5*(1+A22)*E17 -> 3970.9313 | F22: ='P&L Summary'!F5*(1+A22)*F17 -> 4276.3875
A23: 0.3 | B23: ='P&L Summary'!F5*(1+A23)*B17 -> 3176.745 | C23: ='P&L Summary'!F5*(1+A23)*C17 -> 3494.4195 | D23: ='P&L Summary'!F5*(1+A23)*D17 -> 3812.094 | E23: ='P&L Summary'!F5*(1+A23)*E17 -> 4129.7685 | F23: ='P&L Summary'!F5*(1+A23)*F17 -> 4447.443
A25: ↑ Yellow cell = base case (20% growth, 5.5% margin). FY26 EBITDA was ₹2,580 Cr for reference.

Sheet Comps Analysis
A1: DIXON TECHNOLOGIES — COMPARABLE COMPANY ANALYSIS (₹ Crore)
A2: Source: BSE/NSE exchange filings May 2026 · Screener.in · Yahoo Finance · TradingView. All FY26 actuals.
A4: Company | B4: Revenue (₹ Cr) | C4: EBITDA (₹ Cr) | D4: EBITDA Margin | E4: PAT (₹ Cr) | F4: Mkt Cap (₹ Cr) | G4: Net Debt (+debt/−cash) (₹ Cr) | H4: EV (₹ Cr) | I4: EV/EBITDA | J4: P/E (reported) | K4: Rev Growth YoY
A5: Dixon Technologies (NSE:DIXON) | B5: 48873 | C5: 2580 | D5: 0.053 | E5: 1644 | F5: 68549 | G5: -300 | H5: =F5+G5 -> 68249 | I5: =H5/C5 -> 26.453101 | J5: =F5/E5 -> 41.696472 | K5: 0.258 | M5: Subject company. PAT includes ₹670 Cr one-time fair-value gain; adjusted PAT ~₹974 Cr (adj P/E ~70x)
A6: Kaynes Technology (NSE:KAYNES) | B6: 3626 | C6: 574 | D6: 0.158 | E6: 364 | F6: 23824 | G6: 600 | H6: =F6+G6 -> 24424 | I6: =H6/C6 -> 42.550523 | J6: =F6/E6 -> 65.450549 | K6: 0.332 | M6: Industrial/auto EMS. High-margin (15.8%) design-led model. FY26 rev +33%. ECMS beneficiary. Source: BSE FY26 filing, TradingView price ₹4,136.
A7: Amber Enterprises (NSE:AMBER) | B7: 12186 | C7: 970 | D7: 0.08 | E7: 338 | F7: 27586 | G7: 2200 | H7: =F7+G7 -> 29786 | I7: =H7/C7 -> 30.707216 | J7: =F7/E7 -> 81.615385 | K7: 0.22 | M7: AC + electronics EMS. Electronics div grew 49% FY26. Has ₹2,500 Cr QIP debt. Adj PAT before ₹112 Cr impairment. Source: BSE May 16 2026 filing.
A8: PG Electroplast (NSE:PGEL) | B8: 5288 | C8: 307 | D8: 0.058 | E8: 197 | F8: 13861 | G8: 400 | H8: =F8+G8 -> 14261 | I8: =H8/C8 -> 46.452769 | J8: =F8/E8 -> 70.360406 | K8: 0.355 | M8: Consumer appliance EMS (ACs, washing machines). Similar margin profile to Dixon. Source: Screener.in FY26 consolidated.
A9: Syrma SGS Technology (NSE:SYRMA) | B9: 4819 | C9: 578 | D9: 0.12 | E9: 318 | F9: 21326 | G9: -610 | H9: =F9+G9 -> 20716 | I9: =H9/C9 -> 35.84083 | J9: =F9/E9 -> 67.062893 | K9: 0.261 | M9: PCBA/box-build, RFID, defense electronics. High margin (12%). EV/EBITDA 35.9x from Yahoo Finance June 2026.
A11: PEER STATISTICS (Kaynes / Amber / PGEL / Syrma — excluding Dixon)
A12: Peer Mean | B12: =AVERAGE(B6:B9) -> 6479.75 | C12: =AVERAGE(C6:C9) -> 607.25 | D12: =AVERAGE(D6:D9) -> 0.104 | E12: =AVERAGE(E6:E9) -> 304.25 | F12: =AVERAGE(F6:F9) -> 21649.25 | H12: =AVERAGE(H6:H9) -> 22296.75 | I12: =AVERAGE(I6:I9) -> 38.887835 | J12: =AVERAGE(J6:J9) -> 71.122308 | K12: =AVERAGE(K6:K9) -> 0.292
A13: Peer Median | B13: =MEDIAN(B6:B9) -> 5053.5 | C13: =MEDIAN(C6:C9) -> 576 | D13: =MEDIAN(D6:D9) -> 0.1 | E13: =MEDIAN(E6:E9) -> 328 | F13: =MEDIAN(F6:F9) -> 22575 | H13: =MEDIAN(H6:H9) -> 22570 | I13: =MEDIAN(I6:I9) -> 39.195677 | J13: =MEDIAN(J6:J9) -> 68.71165 | K13: =MEDIAN(K6:K9) -> 0.2965
A14: Peer Min | B14: =MIN(B6:B9) -> 3626 | C14: =MIN(C6:C9) -> 307 | D14: =MIN(D6:D9) -> 0.058 | E14: =MIN(E6:E9) -> 197 | F14: =MIN(F6:F9) -> 13861 | H14: =MIN(H6:H9) -> 14261 | I14: =MIN(I6:I9) -> 30.707216 | J14: =MIN(J6:J9) -> 65.450549 | K14: =MIN(K6:K9) -> 0.22
A15: Peer Max | B15: =MAX(B6:B9) -> 12186 | C15: =MAX(C6:C9) -> 970 | D15: =MAX(D6:D9) -> 0.158 | E15: =MAX(E6:E9) -> 364 | F15: =MAX(F6:F9) -> 27586 | H15: =MAX(H6:H9) -> 29786 | I15: =MAX(I6:I9) -> 46.452769 | J15: =MAX(J6:J9) -> 81.615385 | K15: =MAX(K6:K9) -> 0.355
A17: IMPLIED VALUATION FOR DIXON — EV/EBITDA METHOD
A18: Dixon EBITDA FY26 (₹ Cr) | B18: ='P&L Summary'!F6 -> 2580
A19: At Peer Minimum EV/EBITDA | B19: =MIN(I6:I9)*B18 -> 79224.619 | M19: Peer lowest multiple (Amber 30.7x) — most conservative comparable
A20: At Peer Median EV/EBITDA | B20: =MEDIAN(I6:I9)*B18 -> 101124.85 | M20: Central tendency of peer group — base case for comps
A21: At Peer Mean EV/EBITDA | B21: =AVERAGE(I6:I9)*B18 -> 100330.61 | M21: Mean peer multiple — slightly higher than median
A22: At Peer Maximum EV/EBITDA | B22: =MAX(I6:I9)*B18 -> 119848.14 | M22: Peer highest multiple (PGEL 46.4x) — most optimistic
A23: At 20% Discount to Median | B23: =MEDIAN(I6:I9)*0.8*B18 -> 80899.876 | M23: Discount for lower margin (5.3% vs 10.9% peer median). Accounts for Dixon's thinner earnings quality.
A25: IMPLIED PRICE PER SHARE (₹) — EV + Cash − Debt / Shares
A26: Implied Price at Peer Min | B26: =(B19+WACC!B18-WACC!B17)/WACC!B28 -> 13036.823 | M26: Most bearish comps price
A27: Implied Price at Peer Median | B27: =(B20+WACC!B18-WACC!B17)/WACC!B28 -> 16627.024 | M27: Base case comps price
A28: Implied Price at Peer Mean | B28: =(B21+WACC!B18-WACC!B17)/WACC!B28 -> 16496.822
A29: Implied Price at Peer Max | B29: =(B22+WACC!B18-WACC!B17)/WACC!B28 -> 19696.417 | M29: Most bullish comps price
A30: Implied Price at 20% Discount | B30: =(B23+WACC!B18-WACC!B17)/WACC!B28 -> 13311.455 | M30: Margin-adjusted comps price
A32: Current market price (₹) | B32: =WACC!B29 -> 11848 | M32: NSE: DIXON closing price. Compare implied comps prices above vs current to assess relative value.
A34: KEY COMPS INSIGHT — WHAT THIS MEANS FOR YOUR THESIS
A35: 1. Dixon trades at ~26.5x EV/EBITDA vs peer median ~39x — a 32% DISCOUNT to the peer group.
A36: 2. BUT: Dixon's EBITDA margin (5.3%) is far below peers like Kaynes (15.8%) and Syrma (12%) — lower margins deserve lower multiples.
A37: 3. Even at a 20% discount to peer median (~31x), comps imply Dixon price ABOVE current market price → comps say BUY.
A38: 4. DCF base case says HOLD/SELL (₹7,500). Comps say BUY (₹13,000+). The gap is the market's growth premium for PLI/Vivo optionality.
A39: 5. Recommendation: HOLD. Dixon must execute on margin expansion (>6% by FY28) and Vivo approval to close the DCF gap. Comps support the stock near current levels.
